Workbook
Name AnalyteList: DB_04[分析項目]
Name EnableList: EnableOptions[啟用]
Name MediaList: MediaCodes[介質]
Name SampleIDList: Samples[樣品編號]
Name SamplingMethodList: SamplingMethods[採樣方法]
Name StandardStatusList: StandardStatuses[核對狀態]
Name StandardVersionList: VersionCodes[版本代碼]
Name StationList: DB_03[監測點]
Name UnitList: UnitCodes[單位]

Sheet 00_使用說明
B2: 監測資料庫 v3.4｜完整計算效能優化版
B4: 場址設定 | C4: 整本活頁簿共用一個場址
B5: 場址名稱 | C5: 合成示範場址A（非實測） | D5: 場址名稱只在本頁維護。
B7: 操作順序 | C7: 藍色欄輸入資料；灰色欄即時計算。新增時使用表格列。
B8: 1. 建立點位與樣品 | C8: 先在 03 建立點位，再到 01 登錄樣品。點位與樣品選單直接引用資料表，新增表格列會同步延伸。
B9: 2. 輸入檢測結果 | C9: 02 的 H 欄選取樣品，A:D 填寫分析結果。E:G 自動帶入點位、日期與解析值；QA/QC 隨同一列延伸。
B10: 3. 檢查資料 | C10: 07 的 C3 選擇標準、C6 輸入結果序號；02 右側 Y:AG 可篩選全部 QA/QC 判讀。
B12: 目前資料 | C12: 由輸入資料自動更新
B13: 結果筆數 | C13: =COUNTA(Results[原始值])
B14: 樣品數 | C14: =COUNTA(Samples[樣品編號])
B15: NA／未解析結果 | C15: =COUNTA(Results[原始值])-COUNT(Results[解析值])
B16: ND結果筆數 | C16: =COUNTIF(Results[限定符],"ND")
B17: 可解析結果 | C17: =COUNT(Results[解析值])
B19: 使用規則
B20: 欄位顏色 | C20: 藍色＝手動維護；灰色＝公式計算。保留 2025/01–06 實測紀錄；另含六筆標示為合成範例的土壤資料。
B21: 法規標準 | C21: 05頁含土壤39項、地下水50項完整管制項目，並納入監測門檻。地下水第一／二類與土壤一般／食用作物農地分開建檔。
B22: NA與ND | C22: ND解析為0；<或≤界限解析為界限/2；NA與空白不轉0。原始值保留。
B23: 新標準版本 | C23: 在07_QAQC的C3選擇比較版本；目前沿用來源主要門檻對應的地下水第二類。不同介質與類別須選其適用版本。
B24: 容量與新增資料 | C24: 依實際資料列計算，不預填上萬空白列。新增結果請在資料表末列按 Tab 或插入表格列。
B25: 批次新增資料 | C25: 先新增足夠的表格列，再貼入輸入欄。不要覆蓋公式；保持 Excel 自動計算，並啟用自動填入表格公式。
B26: 解析值單位 | C26: G欄解析值沿用結果單位；QA/QC另做標準單位換算，標準比較依原始值。
B27: 井深定義 | C27: 井深與篩管深度以井口向下為正；絕對高程獨立記錄。
B28: 新增介質 | C28: 在04_測項與清單的T欄介質表末格按Tab新增一列，再填入名稱。四處選單會同步更新。
B29: 主檔與清單 | C29: 樣品名稱採「監測點_YYYYMMDD」，以值填入 A 欄；02 的 H 欄選單直接引用樣品資料表。
B30: 深度欄位 | C30: 樣品登錄F欄：土壤為深度起，地下水為水位（井口向下為正）；採樣深度另填E欄。
B31: 繪圖欄位 | C31: 篩選 02 的測項、單位與點位查看結果；展開右側 QA/QC 可檢查格式、重複、單位及標準判讀。

Sheet 01_樣品登錄
A1: 樣品編號 | B1: 監測點 | C1: 採樣日期 | D1: 採樣說明 | E1: 採樣深度(m) | F1: 深度起(m) | G1: 深度迄(m) | H1: 採樣方法 | I1: 採樣單位 | J1: 檢測單位 | K1: 備註 | L1: 介質 | M1: 樣品檢查 | N1: 樣品重複筆數
A2: BH01-S_20260115_01 | B2: BH01-S | C2: 46037 | D2: Campaign 1 | E2: 0.5 | F2: 0 | G2: 1 | H2: 其他 | I2: 合成範例 | J2: 合成範例 | K2: 合成資料；來源 examples/demo/samples.csv；BH01-soil-1-1 | L2: =IF(B2="","",IF(COUNTIF(DB_03[監測點],B2)=1,INDEX(DB_03[預設介質],MATCH(B2,DB_03[監測點],0)),"")) | M2: =IF(COUNTA(A2:K2)=0,"",IF(A2="","缺樣品編號；","")&IF(AND(A2<>"",N2>1),"樣品編號重複；","")&IF(COUNTIFS(DB_03[監測點],B2,DB_03[預設介質],L2,DB_03[啟用],"是")<>1,"點位或介質待核；","")&IF(NOT(ISNUMBER(C2)),"缺採樣日期；","")&IF(AND(L2="土壤",OR(NOT(ISNUMBER(F2)),NOT(ISNUMBER(G2)))),"缺土壤深度；","")&IF(AND(L2="土壤",ISNUMBER(F2),ISNUMBER(G2),OR(F2>G2,F2<0)),"土壤深度起迄錯誤；","")&IF(AND(L2="地下水",F2<>"",NOT(ISNUMBER(F2))),"水位須為數值；","")&IF(AND(L2="地下水",H2=""),"缺採樣方法；","")&IF(AND(B2<>"",L2=""),"監測點未建或重複；","")) | N2: =IF(A2="","",COUNTIF(Samples[樣品編號],A2))
A3: BH01-W_20260115_01 | B3: BH01-W | C3: 46037 | D3: Campaign 1 | E3: 0.5 | F3: 0.2 | H3: 微洗井 | I3: 合成範例 | J3: 合成範例 | K3: 合成資料；來源 examples/demo/samples.csv；BH01-groundwater-1-1 | L3: =IF(B3="","",IF(COUNTIF(DB_03[監測點],B3)=1,INDEX(DB_03[預設介質],MATCH(B3,DB_03[監測點],0)),"")) | M3: =IF(COUNTA(A3:K3)=0,"",IF(A3="","缺樣品編號；","")&IF(AND(A3<>"",N3>1),"樣品編號重複；","")&IF(COUNTIFS(DB_03[監測點],B3,DB_03[預設介質],L3,DB_03[啟用],"是")<>1,"點位或介質待核；","")&IF(NOT(ISNUMBER(C3)),"缺採樣日期；","")&IF(AND(L3="土壤",OR(NOT(ISNUMBER(F3)),NOT(ISNUMBER(G3)))),"缺土壤深度；","")&IF(AND(L3="土壤",ISNUMBER(F3),ISNUMBER(G3),OR(F3>G3,F3<0)),"土壤深度起迄錯誤；","")&IF(AND(L3="地下水",F3<>"",NOT(ISNUMBER(F3))),"水位須為數值；","")&IF(AND(L3="地下水",H3=""),"缺採樣方法；","")&IF(AND(B3<>"",L3=""),"監測點未建或重複；","")) | N3: =IF(A3="","",COUNTIF(Samples[樣品編號],A3))
A4: BH01-S_20260115_02 | B4: BH01-S | C4: 46037 | D4: Campaign 1 | E4: 1.5 | F4: 1 | G4: 2 | H4: 其他 | I4: 合成範例 | J4: 合成範例 | K4: 合成資料；來源 examples/demo/samples.csv；BH01-soil-1-2 | L4: =IF(B4="","",IF(COUNTIF(DB_03[監測點],B4)=1,INDEX(DB_03[預設介質],MATCH(B4,DB_03[監測點],0)),"")) | M4: =IF(COUNTA(A4:K4)=0,"",IF(A4="","缺樣品編號；","")&IF(AND(A4<>"",N4>1),"樣品編號重複；","")&IF(COUNTIFS(DB_03[監測點],B4,DB_03[預設介質],L4,DB_03[啟用],"是")<>1,"點位或介質待核；","")&IF(NOT(ISNUMBER(C4)),"缺採樣日期；","")&IF(AND(L4="土壤",OR(NOT(ISNUMBER(F4)),NOT(ISNUMBER(G4)))),"缺土壤深度；","")&IF(AND(L4="土壤",ISNUMBER(F4),ISNUMBER(G4),OR(F4>G4,F4<0)),"土壤深度起迄錯誤；","")&IF(AND(L4="地下水",F4<>"",NOT(ISNUMBER(F4))),"水位須為數值；","")&IF(AND(L4="地下水",H4=""),"缺採樣方法；","")&IF(AND(B4<>"",L4=""),"監測點未建或重複；","")) | N4: =IF(A4="","",COUNTIF(Samples[樣品編號],A4))
A5: BH01-W_20260115_02 | B5: BH01-W | C5: 46037 | D5: Campaign 1 | E5: 1.5 | H5: 微洗井 | I5: 合成範例 | J5: 合成範例 | K5: 合成資料；來源 examples/demo/samples.csv；BH01-groundwater-1-2 | L5: =IF(B5="","",IF(COUNTIF(DB_03[監測點],B5)=1,INDEX(DB_03[預設介質],MATCH(B5,DB_03[監測點],0)),"")) | M5: =IF(COUNTA(A5:K5)=0,"",IF(A5="","缺樣品編號；","")&IF(AND(A5<>"",N5>1),"樣品編號重複；","")&IF(COUNTIFS(DB_03[監測點],B5,DB_03[預設介質],L5,DB_03[啟用],"是")<>1,"點位或介質待核；","")&IF(NOT(ISNUMBER(C5)),"缺採樣日期；","")&IF(AND(L5="土壤",OR(NOT(ISNUMBER(F5)),NOT(ISNUMBER(G5)))),"缺土壤深度；","")&IF(AND(L5="土壤",ISNUMBER(F5),ISNUMBER(G5),OR(F5>G5,F5<0)),"土壤深度起迄錯誤；","")&IF(AND(L5="地下水",F5<>"",NOT(ISNUMBER(F5))),"水位須為數值；","")&IF(AND(L5="地下水",H5=""),"缺採樣方法；","")&IF(AND(B5<>"",L5=""),"監測點未建或重複；","")) | N5: =IF(A5="","",COUNTIF(Samples[樣品編號],A5))
A6: BH01-S_20260115_03 | B6: BH01-S | C6: 46037 | D6: Campaign 1 | E6: 2.5 | F6: 2 | G6: 3 | H6: 其他 | I6: 合成範例 | J6: 合成範例 | K6: 合成資料；來源 examples/demo/samples.csv；BH01-soil-1-3 | L6: =IF(B6="","",IF(COUNTIF(DB_03[監測點],B6)=1,INDEX(DB_03[預設介質],MATCH(B6,DB_03[監測點],0)),"")) | M6: =IF(COUNTA(A6:K6)=0,"",IF(A6="","缺樣品編號；","")&IF(AND(A6<>"",N6>1),"樣品編號重複；","")&IF(COUNTIFS(DB_03[監測點],B6,DB_03[預設介質],L6,DB_03[啟用],"是")<>1,"點位或介質待核；","")&IF(NOT(ISNUMBER(C6)),"缺採樣日期；","")&IF(AND(L6="土壤",OR(NOT(ISNUMBER(F6)),NOT(ISNUMBER(G6)))),"缺土壤深度；","")&IF(AND(L6="土壤",ISNUMBER(F6),ISNUMBER(G6),OR(F6>G6,F6<0)),"土壤深度起迄錯誤；","")&IF(AND(L6="地下水",F6<>"",NOT(ISNUMBER(F6))),"水位須為數值；","")&IF(AND(L6="地下水",H6=""),"缺採樣方法；","")&IF(AND(B6<>"",L6=""),"監測點未建或重複；","")) | N6: =IF(A6="","",COUNTIF(Samples[樣品編號],A6))
A7: BH01-W_20260115_03 | B7: BH01-W | C7: 46037 | D7: Campaign 1 | E7: 2.5 | H7: 微洗井 | I7: 合成範例 | J7: 合成範例 | K7: 合成資料；來源 examples/demo/samples.csv；BH01-groundwater-1-3 | L7: =IF(B7="","",IF(COUNTIF(DB_03[監測點],B7)=1,INDEX(DB_03[預設介質],MATCH(B7,DB_03[監測點],0)),"")) | M7: =IF(COUNTA(A7:K7)=0,"",IF(A7="","缺樣品編號；","")&IF(AND(A7<>"",N7>1),"樣品編號重複；","")&IF(COUNTIFS(DB_03[監測點],B7,DB_03[預設介質],L7,DB_03[啟用],"是")<>1,"點位或介質待核；","")&IF(NOT(ISNUMBER(C7)),"缺採樣日期；","")&IF(AND(L7="土壤",OR(NOT(ISNUMBER(F7)),NOT(ISNUMBER(G7)))),"缺土壤深度；","")&IF(AND(L7="土壤",ISNUMBER(F7),ISNUMBER(G7),OR(F7>G7,F7<0)),"土壤深度起迄錯誤；","")&IF(AND(L7="地下水",F7<>"",NOT(ISNUMBER(F7))),"水位須為數值；","")&IF(AND(L7="地下水",H7=""),"缺採樣方法；","")&IF(AND(B7<>"",L7=""),"監測點未建或重複；","")) | N7: =IF(A7="","",COUNTIF(Samples[樣品編號],A7))
A8: BH01-S_20260415_01 | B8: BH01-S | C8: 46127 | D8: Campaign 2 | E8: 0.5 | F8: 0 | G8: 1 | H8: 其他 | I8: 合成範例 | J8: 合成範例 | K8: 合成資料；來源 examples/demo/samples.csv；BH01-soil-2-1 | L8: =IF(B8="","",IF(COUNTIF(DB_03[監測點],B8)=1,INDEX(DB_03[預設介質],MATCH(B8,DB_03[監測點],0)),"")) | M8: =IF(COUNTA(A8:K8)=0,"",IF(A8="","缺樣品編號；","")&IF(AND(A8<>"",N8>1),"樣品編號重複；","")&IF(COUNTIFS(DB_03[監測點],B8,DB_03[預設介質],L8,DB_03[啟用],"是")<>1,"點位或介質待核；","")&IF(NOT(ISNUMBER(C8)),"缺採樣日期；","")&IF(AND(L8="土壤",OR(NOT(ISNUMBER(F8)),NOT(ISNUMBER(G8)))),"缺土壤深度；","")&IF(AND(L8="土壤",ISNUMBER(F8),ISNUMBER(G8),OR(F8>G8,F8<0)),"土壤深度起迄錯誤；","")&IF(AND(L8="地下水",F8<>"",NOT(ISNUMBER(F8))),"水位須為數值；","")&IF(AND(L8="地下水",H8=""),"缺採樣方法；","")&IF(AND(B8<>"",L8=""),"監測點未建或重複；","")) | N8: =IF(A8="","",COUNTIF(Samples[樣品編號],A8))
A9: BH01-W_20260415_01 | B9: BH01-W | C9: 46127 | D9: Campaign 2 | E9: 0.5 | F9: 0.2 | H9: 微洗井 | I9: 合成範例 | J9: 合成範例 | K9: 合成資料；來源 examples/demo/samples.csv；BH01-groundwater-2-1 | L9: =IF(B9="","",IF(COUNTIF(DB_03[監測點],B9)=1,INDEX(DB_03[預設介質],MATCH(B9,DB_03[監測點],0)),"")) | M9: =IF(COUNTA(A9:K9)=0,"",IF(A9="","缺樣品編號；","")&IF(AND(A9<>"",N9>1),"樣品編號重複；","")&IF(COUNTIFS(DB_03[監測點],B9,DB_03[預設介質],L9,DB_03[啟用],"是")<>1,"點位或介質待核；","")&IF(NOT(ISNUMBER(C9)),"缺採樣日期；","")&IF(AND(L9="土壤",OR(NOT(ISNUMBER(F9)),NOT(ISNUMBER(G9)))),"缺土壤深度；","")&IF(AND(L9="土壤",ISNUMBER(F9),ISNUMBER(G9),OR(F9>G9,F9<0)),"土壤深度起迄錯誤；","")&IF(AND(L9="地下水",F9<>"",NOT(ISNUMBER(F9))),"水位須為數值；","")&IF(AND(L9="地下水",H9=""),"缺採樣方法；","")&IF(AND(B9<>"",L9=""),"監測點未建或重複；","")) | N9: =IF(A9="","",COUNTIF(Samples[樣品編號],A9))
A10: BH01-S_20260415_02 | B10: BH01-S | C10: 46127 | D10: Campaign 2 | E10: 1.5 | F10: 1 | G10: 2 | H10: 其他 | I10: 合成範例 | J10: 合成範例 | K10: 合成資料；來源 examples/demo/samples.csv；BH01-soil-2-2 | L10: =IF(B10="","",IF(COUNTIF(DB_03[監測點],B10)=1,INDEX(DB_03[預設介質],MATCH(B10,DB_03[監測點],0)),"")) | M10: =IF(COUNTA(A10:K10)=0,"",IF(A10="","缺樣品編號；","")&IF(AND(A10<>"",N10>1),"樣品編號重複；","")&IF(COUNTIFS(DB_03[監測點],B10,DB_03[預設介質],L10,DB_03[啟用],"是")<>1,"點位或介質待核；","")&IF(NOT(ISNUMBER(C10)),"缺採樣日期；","")&IF(AND(L10="土壤",OR(NOT(ISNUMBER(F10)),NOT(ISNUMBER(G10)))),"缺土壤深度；","")&IF(AND(L10="土壤",ISNUMBER(F10),ISNUMBER(G10),OR(F10>G10,F10<0)),"土壤深度起迄錯誤；","")&IF(AND(L10="地下水",F10<>"",NOT(ISNUMBER(F10))),"水位須為數值；","")&IF(AND(L10="地下水",H10=""),"缺採樣方法；","")&IF(AND(B10<>"",L10=""),"監測點未建或重複；","")) | N10: =IF(A10="","",COUNTIF(Samples[樣品編號],A10))
A11: BH01-W_20260415_02 | B11: BH01-W | C11: 46127 | D11: Campaign 2 | E11: 1.5 | H11: 微洗井 | I11: 合成範例 | J11: 合成範例 | K11: 合成資料；來源 examples/demo/samples.csv；BH01-groundwater-2-2 | L11: =IF(B11="","",IF(COUNTIF(DB_03[監測點],B11)=1,INDEX(DB_03[預設介質],MATCH(B11,DB_03[監測點],0)),"")) | M11: =IF(COUNTA(A11:K11)=0,"",IF(A11="","缺樣品編號；","")&IF(AND(A11<>"",N11>1),"樣品編號重複；","")&IF(COUNTIFS(DB_03[監測點],B11,DB_03[預設介質],L11,DB_03[啟用],"是")<>1,"點位或介質待核；","")&IF(NOT(ISNUMBER(C11)),"缺採樣日期；","")&IF(AND(L11="土壤",OR(NOT(ISNUMBER(F11)),NOT(ISNUMBER(G11)))),"缺土壤深度；","")&IF(AND(L11="土壤",ISNUMBER(F11),ISNUMBER(G11),OR(F11>G11,F11<0)),"土壤深度起迄錯誤；","")&IF(AND(L11="地下水",F11<>"",NOT(ISNUMBER(F11))),"水位須為數值；","")&IF(AND(L11="地下水",H11=""),"缺採樣方法；","")&IF(AND(B11<>"",L11=""),"監測點未建或重複；","")) | N11: =IF(A11="","",COUNTIF(Samples[樣品編號],A11))
A12: BH01-S_20260415_03 | B12: BH01-S | C12: 46127 | D12: Campaign 2 | E12: 2.5 | F12: 2 | G12: 3 | H12: 其他 | I12: 合成範例 | J12: 合成範例 | K12: 合成資料；來源 examples/demo/samples.csv；BH01-soil-2-3 | L12: =IF(B12="","",IF(COUNTIF(DB_03[監測點],B12)=1,INDEX(DB_03[預設介質],MATCH(B12,DB_03[監測點],0)),"")) | M12: =IF(COUNTA(A12:K12)=0,"",IF(A12="","缺樣品編號；","")&IF(AND(A12<>"",N12>1),"樣品編號重複；","")&IF(COUNTIFS(DB_03[監測點],B12,DB_03[預設介質],L12,DB_03[啟用],"是")<>1,"點位或介質待核；","")&IF(NOT(ISNUMBER(C12)),"缺採樣日期；","")&IF(AND(L12="土壤",OR(NOT(ISNUMBER(F12)),NOT(ISNUMBER(G12)))),"缺土壤深度；","")&IF(AND(L12="土壤",ISNUMBER(F12),ISNUMBER(G12),OR(F12>G12,F12<0)),"土壤深度起迄錯誤；","")&IF(AND(L12="地下水",F12<>"",NOT(ISNUMBER(F12))),"水位須為數值；","")&IF(AND(L12="地下水",H12=""),"缺採樣方法；","")&IF(AND(B12<>"",L12=""),"監測點未建或重複；","")) | N12: =IF(A12="","",COUNTIF(Samples[樣品編號],A12))
A13: BH01-W_20260415_03 | B13: BH01-W | C13: 46127 | D13: Campaign 2 | E13: 2.5 | H13: 微洗井 | I13: 合成範例 | J13: 合成範例 | K13: 合成資料；來源 examples/demo/samples.csv；BH01-groundwater-2-3 | L13: =IF(B13="","",IF(COUNTIF(DB_03[監測點],B13)=1,INDEX(DB_03[預設介質],MATCH(B13,DB_03[監測點],0)),"")) | M13: =IF(COUNTA(A13:K13)=0,"",IF(A13="","缺樣品編號；","")&IF(AND(A13<>"",N13>1),"樣品編號重複；","")&IF(COUNTIFS(DB_03[監測點],B13,DB_03[預設介質],L13,DB_03[啟用],"是")<>1,"點位或介質待核；","")&IF(NOT(ISNUMBER(C13)),"缺採樣日期；","")&IF(AND(L13="土壤",OR(NOT(ISNUMBER(F13)),NOT(ISNUMBER(G13)))),"缺土壤深度；","")&IF(AND(L13="土壤",ISNUMBER(F13),ISNUMBER(G13),OR(F13>G13,F13<0)),"土壤深度起迄錯誤；","")&IF(AND(L13="地下水",F13<>"",NOT(ISNUMBER(F13))),"水位須為數值；","")&IF(AND(L13="地下水",H13=""),"缺採樣方法；","")&IF(AND(B13<>"",L13=""),"監測點未建或重複；","")) | N13: =IF(A13="","",COUNTIF(Samples[樣品編號],A13))
A14: BH02-S_20260115_01 | B14: BH02-S | C14: 46037 | D14: Campaign 1 | E14: 0.5 | F14: 0 | G14: 1 | H14: 其他 | I14: 合成範例 | J14: 合成範例 | K14: 合成資料；來源 examples/demo/samples.csv；BH02-soil-1-1 | L14: =IF(B14="","",IF(COUNTIF(DB_03[監測點],B14)=1,INDEX(DB_03[預設介質],MATCH(B14,DB_03[監測點],0)),"")) | M14: =IF(COUNTA(A14:K14)=0,"",IF(A14="","缺樣品編號；","")&IF(AND(A14<>"",N14>1),"樣品編號重複；","")&IF(COUNTIFS(DB_03[監測點],B14,DB_03[預設介質],L14,DB_03[啟用],"是")<>1,"點位或介質待核；","")&IF(NOT(ISNUMBER(C14)),"缺採樣日期；","")&IF(AND(L14="土壤",OR(NOT(ISNUMBER(F14)),NOT(ISNUMBER(G14)))),"缺土壤深度；","")&IF(AND(L14="土壤",ISNUMBER(F14),ISNUMBER(G14),OR(F14>G14,F14<0)),"土壤深度起迄錯誤；","")&IF(AND(L14="地下水",F14<>"",NOT(ISNUMBER(F14))),"水位須為數值；","")&IF(AND(L14="地下水",H14=""),"缺採樣方法；","")&IF(AND(B14<>"",L14=""),"監測點未建或重複；","")) | N14: =IF(A14="","",COUNTIF(Samples[樣品編號],A14))
A15: BH02-W_20260115_01 | B15: BH02-W | C15: 46037 | D15: Campaign 1 | E15: 0.5 | F15: 0.2 | H15: 微洗井 | I15: 合成範例 | J15: 合成範例 | K15: 合成資料；來源 examples/demo/samples.csv；BH02-groundwater-1-1 | L15: =IF(B15="","",IF(COUNTIF(DB_03[監測點],B15)=1,INDEX(DB_03[預設介質],MATCH(B15,DB_03[監測點],0)),"")) | M15: =IF(COUNTA(A15:K15)=0,"",IF(A15="","缺樣品編號；","")&IF(AND(A15<>"",N15>1),"樣品編號重複；","")&IF(COUNTIFS(DB_03[監測點],B15,DB_03[預設介質],L15,DB_03[啟用],"是")<>1,"點位或介質待核；","")&IF(NOT(ISNUMBER(C15)),"缺採樣日期；","")&IF(AND(L15="土壤",OR(NOT(ISNUMBER(F15)),NOT(ISNUMBER(G15)))),"缺土壤深度；","")&IF(AND(L15="土壤",ISNUMBER(F15),ISNUMBER(G15),OR(F15>G15,F15<0)),"土壤深度起迄錯誤；","")&IF(AND(L15="地下水",F15<>"",NOT(ISNUMBER(F15))),"水位須為數值；","")&IF(AND(L15="地下水",H15=""),"缺採樣方法；","")&IF(AND(B15<>"",L15=""),"監測點未建或重複；","")) | N15: =IF(A15="","",COUNTIF(Samples[樣品編號],A15))
A16: BH02-S_20260115_02 | B16: BH02-S | C16: 46037 | D16: Campaign 1 | E16: 1.5 | F16: 1 | G16: 2 | H16: 其他 | I16: 合成範例 | J16: 合成範例 | K16: 合成資料；來源 examples/demo/samples.csv；BH02-soil-1-2 | L16: =IF(B16="","",IF(COUNTIF(DB_03[監測點],B16)=1,INDEX(DB_03[預設介質],MATCH(B16,DB_03[監測點],0)),"")) | M16: =IF(COUNTA(A16:K16)=0,"",IF(A16="","缺樣品編號；","")&IF(AND(A16<>"",N16>1),"樣品編號重複；","")&IF(COUNTIFS(DB_03[監測點],B16,DB_03[預設介質],L16,DB_03[啟用],"是")<>1,"點位或介質待核；","")&IF(NOT(ISNUMBER(C16)),"缺採樣日期；","")&IF(AND(L16="土壤",OR(NOT(ISNUMBER(F16)),NOT(ISNUMBER(G16)))),"缺土壤深度；","")&IF(AND(L16="土壤",ISNUMBER(F16),ISNUMBER(G16),OR(F16>G16,F16<0)),"土壤深度起迄錯誤；","")&IF(AND(L16="地下水",F16<>"",NOT(ISNUMBER(F16))),"水位須為數值；","")&IF(AND(L16="地下水",H16=""),"缺採樣方法；","")&IF(AND(B16<>"",L16=""),"監測點未建或重複；","")) | N16: =IF(A16="","",COUNTIF(Samples[樣品編號],A16))
A17: BH02-W_20260115_02 | B17: BH02-W | C17: 46037 | D17: Campaign 1 | E17: 1.5 | H17: 微洗井 | I17: 合成範例 | J17: 合成範例 | K17: 合成資料；來源 examples/demo/samples.csv；BH02-groundwater-1-2 | L17: =IF(B17="","",IF(COUNTIF(DB_03[監測點],B17)=1,INDEX(DB_03[預設介質],MATCH(B17,DB_03[監測點],0)),"")) | M17: =IF(COUNTA(A17:K17)=0,"",IF(A17="","缺樣品編號；","")&IF(AND(A17<>"",N17>1),"樣品編號重複；","")&IF(COUNTIFS(DB_03[監測點],B17,DB_03[預設介質],L17,DB_03[啟用],"是")<>1,"點位或介質待核；","")&IF(NOT(ISNUMBER(C17)),"缺採樣日期；","")&IF(AND(L17="土壤",OR(NOT(ISNUMBER(F17)),NOT(ISNUMBER(G17)))),"缺土壤深度；","")&IF(AND(L17="土壤",ISNUMBER(F17),ISNUMBER(G17),OR(F17>G17,F17<0)),"土壤深度起迄錯誤；","")&IF(AND(L17="地下水",F17<>"",NOT(ISNUMBER(F17))),"水位須為數值；","")&IF(AND(L17="地下水",H17=""),"缺採樣方法；","")&IF(AND(B17<>"",L17=""),"監測點未建或重複；","")) | N17: =IF(A17="","",COUNTIF(Samples[樣品編號],A17))
A18: BH02-S_20260115_03 | B18: BH02-S | C18: 46037 | D18: Campaign 1 | E18: 2.5 | F18: 2 | G18: 3 | H18: 其他 | I18: 合成範例 | J18: 合成範例 | K18: 合成資料；來源 examples/demo/samples.csv；BH02-soil-1-3 | L18: =IF(B18="","",IF(COUNTIF(DB_03[監測點],B18)=1,INDEX(DB_03[預設介質],MATCH(B18,DB_03[監測點],0)),"")) | M18: =IF(COUNTA(A18:K18)=0,"",IF(A18="","缺樣品編號；","")&IF(AND(A18<>"",N18>1),"樣品編號重複；","")&IF(COUNTIFS(DB_03[監測點],B18,DB_03[預設介質],L18,DB_03[啟用],"是")<>1,"點位或介質待核；","")&IF(NOT(ISNUMBER(C18)),"缺採樣日期；","")&IF(AND(L18="土壤",OR(NOT(ISNUMBER(F18)),NOT(ISNUMBER(G18)))),"缺土壤深度；","")&IF(AND(L18="土壤",ISNUMBER(F18),ISNUMBER(G18),OR(F18>G18,F18<0)),"土壤深度起迄錯誤；","")&IF(AND(L18="地下水",F18<>"",NOT(ISNUMBER(F18))),"水位須為數值；","")&IF(AND(L18="地下水",H18=""),"缺採樣方法；","")&IF(AND(B18<>"",L18=""),"監測點未建或重複；","")) | N18: =IF(A18="","",COUNTIF(Samples[樣品編號],A18))
A19: BH02-W_20260115_03 | B19: BH02-W | C19: 46037 | D19: Campaign 1 | E19: 2.5 | H19: 微洗井 | I19: 合成範例 | J19: 合成範例 | K19: 合成資料；來源 examples/demo/samples.csv；BH02-groundwater-1-3 | L19: =IF(B19="","",IF(COUNTIF(DB_03[監測點],B19)=1,INDEX(DB_03[預設介質],MATCH(B19,DB_03[監測點],0)),"")) | M19: =IF(COUNTA(A19:K19)=0,"",IF(A19="","缺樣品編號；","")&IF(AND(A19<>"",N19>1),"樣品編號重複；","")&IF(COUNTIFS(DB_03[監測點],B19,DB_03[預設介質],L19,DB_03[啟用],"是")<>1,"點位或介質待核；","")&IF(NOT(ISNUMBER(C19)),"缺採樣日期；","")&IF(AND(L19="土壤",OR(NOT(ISNUMBER(F19)),NOT(ISNUMBER(G19)))),"缺土壤深度；","")&IF(AND(L19="土壤",ISNUMBER(F19),ISNUMBER(G19),OR(F19>G19,F19<0)),"土壤深度起迄錯誤；","")&IF(AND(L19="地下水",F19<>"",NOT(ISNUMBER(F19))),"水位須為數值；","")&IF(AND(L19="地下水",H19=""),"缺採樣方法；","")&IF(AND(B19<>"",L19=""),"監測點未建或重複；","")) | N19: =IF(A19="","",COUNTIF(Samples[樣品編號],A19))
A20: BH02-S_20260415_01 | B20: BH02-S | C20: 46127 | D20: Campaign 2 | E20: 0.5 | F20: 0 | G20: 1 | H20: 其他 | I20: 合成範例 | J20: 合成範例 | K20: 合成資料；來源 examples/demo/samples.csv；BH02-soil-2-1 | L20: =IF(B20="","",IF(COUNTIF(DB_03[監測點],B20)=1,INDEX(DB_03[預設介質],MATCH(B20,DB_03[監測點],0)),"")) | M20: =IF(COUNTA(A20:K20)=0,"",IF(A20="","缺樣品編號；","")&IF(AND(A20<>"",N20>1),"樣品編號重複；","")&IF(COUNTIFS(DB_03[監測點],B20,DB_03[預設介質],L20,DB_03[啟用],"是")<>1,"點位或介質待核；","")&IF(NOT(ISNUMBER(C20)),"缺採樣日期；","")&IF(AND(L20="土壤",OR(NOT(ISNUMBER(F20)),NOT(ISNUMBER(G20)))),"缺土壤深度；","")&IF(AND(L20="土壤",ISNUMBER(F20),ISNUMBER(G20),OR(F20>G20,F20<0)),"土壤深度起迄錯誤；","")&IF(AND(L20="地下水",F20<>"",NOT(ISNUMBER(F20))),"水位須為數值；","")&IF(AND(L20="地下水",H20=""),"缺採樣方法；","")&IF(AND(B20<>"",L20=""),"監測點未建或重複；","")) | N20: =IF(A20="","",COUNTIF(Samples[樣品編號],A20))
A21: BH02-W_20260415_01 | B21: BH02-W | C21: 46127 | D21: Campaign 2 | E21: 0.5 | F21: 0.2 | H21: 微洗井 | I21: 合成範例 | J21: 合成範例 | K21: 合成資料；來源 examples/demo/samples.csv；BH02-groundwater-2-1 | L21: =IF(B21="","",IF(COUNTIF(DB_03[監測點],B21)=1,INDEX(DB_03[預設介質],MATCH(B21,DB_03[監測點],0)),"")) | M21: =IF(COUNTA(A21:K21)=0,"",IF(A21="","缺樣品編號；","")&IF(AND(A21<>"",N21>1),"樣品編號重複；","")&IF(COUNTIFS(DB_03[監測點],B21,DB_03[預設介質],L21,DB_03[啟用],"是")<>1,"點位或介質待核；","")&IF(NOT(ISNUMBER(C21)),"缺採樣日期；","")&IF(AND(L21="土壤",OR(NOT(ISNUMBER(F21)),NOT(ISNUMBER(G21)))),"缺土壤深度；","")&IF(AND(L21="土壤",ISNUMBER(F21),ISNUMBER(G21),OR(F21>G21,F21<0)),"土壤深度起迄錯誤；","")&IF(AND(L21="地下水",F21<>"",NOT(ISNUMBER(F21))),"水位須為數值；","")&IF(AND(L21="地下水",H21=""),"缺採樣方法；","")&IF(AND(B21<>"",L21=""),"監測點未建或重複；","")) | N21: =IF(A21="","",COUNTIF(Samples[樣品編號],A21))
A22: BH02-S_20260415_02 | B22: BH02-S | C22: 46127 | D22: Campaign 2 | E22: 1.5 | F22: 1 | G22: 2 | H22: 其他 | I22: 合成範例 | J22: 合成範例 | K22: 合成資料；來源 examples/demo/samples.csv；BH02-soil-2-2 | L22: =IF(B22="","",IF(COUNTIF(DB_03[監測點],B22)=1,INDEX(DB_03[預設介質],MATCH(B22,DB_03[監測點],0)),"")) | M22: =IF(COUNTA(A22:K22)=0,"",IF(A22="","缺樣品編號；","")&IF(AND(A22<>"",N22>1),"樣品編號重複；","")&IF(COUNTIFS(DB_03[監測點],B22,DB_03[預設介質],L22,DB_03[啟用],"是")<>1,"點位或介質待核；","")&IF(NOT(ISNUMBER(C22)),"缺採樣日期；","")&IF(AND(L22="土壤",OR(NOT(ISNUMBER(F22)),NOT(ISNUMBER(G22)))),"缺土壤深度；","")&IF(AND(L22="土壤",ISNUMBER(F22),ISNUMBER(G22),OR(F22>G22,F22<0)),"土壤深度起迄錯誤；","")&IF(AND(L22="地下水",F22<>"",NOT(ISNUMBER(F22))),"水位須為數值；","")&IF(AND(L22="地下水",H22=""),"缺採樣方法；","")&IF(AND(B22<>"",L22=""),"監測點未建或重複；","")) | N22: =IF(A22="","",COUNTIF(Samples[樣品編號],A22))
A23: BH02-W_20260415_02 | B23: BH02-W | C23: 46127 | D23: Campaign 2 | E23: 1.5 | H23: 微洗井 | I23: 合成範例 | J23: 合成範例 | K23: 合成資料；來源 examples/demo/samples.csv；BH02-groundwater-2-2 | L23: =IF(B23="","",IF(COUNTIF(DB_03[監測點],B23)=1,INDEX(DB_03[預設介質],MATCH(B23,DB_03[監測點],0)),"")) | M23: =IF(COUNTA(A23:K23)=0,"",IF(A23="","缺樣品編號；","")&IF(AND(A23<>"",N23>1),"樣品編號重複；","")&IF(COUNTIFS(DB_03[監測點],B23,DB_03[預設介質],L23,DB_03[啟用],"是")<>1,"點位或介質待核；","")&IF(NOT(ISNUMBER(C23)),"缺採樣日期；","")&IF(AND(L23="土壤",OR(NOT(ISNUMBER(F23)),NOT(ISNUMBER(G23)))),"缺土壤深度；","")&IF(AND(L23="土壤",ISNUMBER(F23),ISNUMBER(G23),OR(F23>G23,F23<0)),"土壤深度起迄錯誤；","")&IF(AND(L23="地下水",F23<>"",NOT(ISNUMBER(F23))),"水位須為數值；","")&IF(AND(L23="地下水",H23=""),"缺採樣方法；","")&IF(AND(B23<>"",L23=""),"監測點未建或重複；","")) | N23: =IF(A23="","",COUNTIF(Samples[樣品編號],A23))
A24: BH02-S_20260415_03 | B24: BH02-S | C24: 46127 | D24: Campaign 2 | E24: 2.5 | F24: 2 | G24: 3 | H24: 其他 | I24: 合成範例 | J24: 合成範例 | K24: 合成資料；來源 examples/demo/samples.csv；BH02-soil-2-3 | L24: =IF(B24="","",IF(COUNTIF(DB_03[監測點],B24)=1,INDEX(DB_03[預設介質],MATCH(B24,DB_03[監測點],0)),"")) | M24: =IF(COUNTA(A24:K24)=0,"",IF(A24="","缺樣品編號；","")&IF(AND(A24<>"",N24>1),"樣品編號重複；","")&IF(COUNTIFS(DB_03[監測點],B24,DB_03[預設介質],L24,DB_03[啟用],"是")<>1,"點位或介質待核；","")&IF(NOT(ISNUMBER(C24)),"缺採樣日期；","")&IF(AND(L24="土壤",OR(NOT(ISNUMBER(F24)),NOT(ISNUMBER(G24)))),"缺土壤深度；","")&IF(AND(L24="土壤",ISNUMBER(F24),ISNUMBER(G24),OR(F24>G24,F24<0)),"土壤深度起迄錯誤；","")&IF(AND(L24="地下水",F24<>"",NOT(ISNUMBER(F24))),"水位須為數值；","")&IF(AND(L24="地下水",H24=""),"缺採樣方法；","")&IF(AND(B24<>"",L24=""),"監測點未建或重複；","")) | N24: =IF(A24="","",COUNTIF(Samples[樣品編號],A24))
A25: BH02-W_20260415_03 | B25: BH02-W | C25: 46127 | D25: Campaign 2 | E25: 2.5 | H25: 微洗井 | I25: 合成範例 | J25: 合成範例 | K25: 合成資料；來源 examples/demo/samples.csv；BH02-groundwater-2-3 | L25: =IF(B25="","",IF(COUNTIF(DB_03[監測點],B25)=1,INDEX(DB_03[預設介質],MATCH(B25,DB_03[監測點],0)),"")) | M25: =IF(COUNTA(A25:K25)=0,"",IF(A25="","缺樣品編號；","")&IF(AND(A25<>"",N25>1),"樣品編號重複；","")&IF(COUNTIFS(DB_03[監測點],B25,DB_03[預設介質],L25,DB_03[啟用],"是")<>1,"點位或介質待核；","")&IF(NOT(ISNUMBER(C25)),"缺採樣日期；","")&IF(AND(L25="土壤",OR(NOT(ISNUMBER(F25)),NOT(ISNUMBER(G25)))),"缺土壤深度；","")&IF(AND(L25="土壤",ISNUMBER(F25),ISNUMBER(G25),OR(F25>G25,F25<0)),"土壤深度起迄錯誤；","")&IF(AND(L25="地下水",F25<>"",NOT(ISNUMBER(F25))),"水位須為數值；","")&IF(AND(L25="地下水",H25=""),"缺採樣方法；","")&IF(AND(B25<>"",L25=""),"監測點未建或重複；","")) | N25: =IF(A25="","",COUNTIF(Samples[樣品編號],A25))
A26: BH03-S_20260115_01 | B26: BH03-S | C26: 46037 | D26: Campaign 1 | E26: 0.5 | F26: 0 | G26: 1 | H26: 其他 | I26: 合成範例 | J26: 合成範例 | K26: 合成資料；來源 examples/demo/samples.csv；BH03-soil-1-1 | L26: =IF(B26="","",IF(COUNTIF(DB_03[監測點],B26)=1,INDEX(DB_03[預設介質],MATCH(B26,DB_03[監測點],0)),"")) | M26: =IF(COUNTA(A26:K26)=0,"",IF(A26="","缺樣品編號；","")&IF(AND(A26<>"",N26>1),"樣品編號重複；","")&IF(COUNTIFS(DB_03[監測點],B26,DB_03[預設介質],L26,DB_03[啟用],"是")<>1,"點位或介質待核；","")&IF(NOT(ISNUMBER(C26)),"缺採樣日期；","")&IF(AND(L26="土壤",OR(NOT(ISNUMBER(F26)),NOT(ISNUMBER(G26)))),"缺土壤深度；","")&IF(AND(L26="土壤",ISNUMBER(F26),ISNUMBER(G26),OR(F26>G26,F26<0)),"土壤深度起迄錯誤；","")&IF(AND(L26="地下水",F26<>"",NOT(ISNUMBER(F26))),"水位須為數值；","")&IF(AND(L26="地下水",H26=""),"缺採樣方法；","")&IF(AND(B26<>"",L26=""),"監測點未建或重複；","")) | N26: =IF(A26="","",COUNTIF(Samples[樣品編號],A26))
A27: BH03-W_20260115_01 | B27: BH03-W | C27: 46037 | D27: Campaign 1 | E27: 0.5 | F27: 0.2 | H27: 微洗井 | I27: 合成範例 | J27: 合成範例 | K27: 合成資料；來源 examples/demo/samples.csv；BH03-groundwater-1-1 | L27: =IF(B27="","",IF(COUNTIF(DB_03[監測點],B27)=1,INDEX(DB_03[預設介質],MATCH(B27,DB_03[監測點],0)),"")) | M27: =IF(COUNTA(A27:K27)=0,"",IF(A27="","缺樣品編號；","")&IF(AND(A27<>"",N27>1),"樣品編號重複；","")&IF(COUNTIFS(DB_03[監測點],B27,DB_03[預設介質],L27,DB_03[啟用],"是")<>1,"點位或介質待核；","")&IF(NOT(ISNUMBER(C27)),"缺採樣日期；","")&IF(AND(L27="土壤",OR(NOT(ISNUMBER(F27)),NOT(ISNUMBER(G27)))),"缺土壤深度；","")&IF(AND(L27="土壤",ISNUMBER(F27),ISNUMBER(G27),OR(F27>G27,F27<0)),"土壤深度起迄錯誤；","")&IF(AND(L27="地下水",F27<>"",NOT(ISNUMBER(F27))),"水位須為數值；","")&IF(AND(L27="地下水",H27=""),"缺採樣方法；","")&IF(AND(B27<>"",L27=""),"監測點未建或重複；","")) | N27: =IF(A27="","",COUNTIF(Samples[樣品編號],A27))
A28: BH03-S_20260115_02 | B28: BH03-S | C28: 46037 | D28: Campaign 1 | E28: 1.5 | F28: 1 | G28: 2 | H28: 其他 | I28: 合成範例 | J28: 合成範例 | K28: 合成資料；來源 examples/demo/samples.csv；BH03-soil-1-2 | L28: =IF(B28="","",IF(COUNTIF(DB_03[監測點],B28)=1,INDEX(DB_03[預設介質],MATCH(B28,DB_03[監測點],0)),"")) | M28: =IF(COUNTA(A28:K28)=0,"",IF(A28="","缺樣品編號；","")&IF(AND(A28<>"",N28>1),"樣品編號重複；","")&IF(COUNTIFS(DB_03[監測點],B28,DB_03[預設介質],L28,DB_03[啟用],"是")<>1,"點位或介質待核；","")&IF(NOT(ISNUMBER(C28)),"缺採樣日期；","")&IF(AND(L28="土壤",OR(NOT(ISNUMBER(F28)),NOT(ISNUMBER(G28)))),"缺土壤深度；","")&IF(AND(L28="土壤",ISNUMBER(F28),ISNUMBER(G28),OR(F28>G28,F28<0)),"土壤深度起迄錯誤；","")&IF(AND(L28="地下水",F28<>"",NOT(ISNUMBER(F28))),"水位須為數值；","")&IF(AND(L28="地下水",H28=""),"缺採樣方法；","")&IF(AND(B28<>"",L28=""),"監測點未建或重複；","")) | N28: =IF(A28="","",COUNTIF(Samples[樣品編號],A28))
A29: BH03-W_20260115_02 | B29: BH03-W | C29: 46037 | D29: Campaign 1 | E29: 1.5 | H29: 微洗井 | I29: 合成範例 | J29: 合成範例 | K29: 合成資料；來源 examples/demo/samples.csv；BH03-groundwater-1-2 | L29: =IF(B29="","",IF(COUNTIF(DB_03[監測點],B29)=1,INDEX(DB_03[預設介質],MATCH(B29,DB_03[監測點],0)),"")) | M29: =IF(COUNTA(A29:K29)=0,"",IF(A29="","缺樣品編號；","")&IF(AND(A29<>"",N29>1),"樣品編號重複；","")&IF(COUNTIFS(DB_03[監測點],B29,DB_03[預設介質],L29,DB_03[啟用],"是")<>1,"點位或介質待核；","")&IF(NOT(ISNUMBER(C29)),"缺採樣日期；","")&IF(AND(L29="土壤",OR(NOT(ISNUMBER(F29)),NOT(ISNUMBER(G29)))),"缺土壤深度；","")&IF(AND(L29="土壤",ISNUMBER(F29),ISNUMBER(G29),OR(F29>G29,F29<0)),"土壤深度起迄錯誤；","")&IF(AND(L29="地下水",F29<>"",NOT(ISNUMBER(F29))),"水位須為數值；","")&IF(AND(L29="地下水",H29=""),"缺採樣方法；","")&IF(AND(B29<>"",L29=""),"監測點未建或重複；","")) | N29: =IF(A29="","",COUNTIF(Samples[樣品編號],A29))
A30: BH03-S_20260115_03 | B30: BH03-S | C30: 46037 | D30: Campaign 1 | E30: 2.5 | F30: 2 | G30: 3 | H30: 其他 | I30: 合成範例 | J30: 合成範例 | K30: 合成資料；來源 examples/demo/samples.csv；BH03-soil-1-3 | L30: =IF(B30="","",IF(COUNTIF(DB_03[監測點],B30)=1,INDEX(DB_03[預設介質],MATCH(B30,DB_03[監測點],0)),"")) | M30: =IF(COUNTA(A30:K30)=0,"",IF(A30="","缺樣品編號；","")&IF(AND(A30<>"",N30>1),"樣品編號重複；","")&IF(COUNTIFS(DB_03[監測點],B30,DB_03[預設介質],L30,DB_03[啟用],"是")<>1,"點位或介質待核；","")&IF(NOT(ISNUMBER(C30)),"缺採樣日期；","")&IF(AND(L30="土壤",OR(NOT(ISNUMBER(F30)),NOT(ISNUMBER(G30)))),"缺土壤深度；","")&IF(AND(L30="土壤",ISNUMBER(F30),ISNUMBER(G30),OR(F30>G30,F30<0)),"土壤深度起迄錯誤；","")&IF(AND(L30="地下水",F30<>"",NOT(ISNUMBER(F30))),"水位須為數值；","")&IF(AND(L30="地下水",H30=""),"缺採樣方法；","")&IF(AND(B30<>"",L30=""),"監測點未建或重複；","")) | N30: =IF(A30="","",COUNTIF(Samples[樣品編號],A30))
A31: BH03-W_20260115_03 | B31: BH03-W | C31: 46037 | D31: Campaign 1 | E31: 2.5 | H31: 微洗井 | I31: 合成範例 | J31: 合成範例 | K31: 合成資料；來源 examples/demo/samples.csv；BH03-groundwater-1-3 | L31: =IF(B31="","",IF(COUNTIF(DB_03[監測點],B31)=1,INDEX(DB_03[預設介質],MATCH(B31,DB_03[監測點],0)),"")) | M31: =IF(COUNTA(A31:K31)=0,"",IF(A31="","缺樣品編號；","")&IF(AND(A31<>"",N31>1),"樣品編號重複；","")&IF(COUNTIFS(DB_03[監測點],B31,DB_03[預設介質],L31,DB_03[啟用],"是")<>1,"點位或介質待核；","")&IF(NOT(ISNUMBER(C31)),"缺採樣日期；","")&IF(AND(L31="土壤",OR(NOT(ISNUMBER(F31)),NOT(ISNUMBER(G31)))),"缺土壤深度；","")&IF(AND(L31="土壤",ISNUMBER(F31),ISNUMBER(G31),OR(F31>G31,F31<0)),"土壤深度起迄錯誤；","")&IF(AND(L31="地下水",F31<>"",NOT(ISNUMBER(F31))),"水位須為數值；","")&IF(AND(L31="地下水",H31=""),"缺採樣方法；","")&IF(AND(B31<>"",L31=""),"監測點未建或重複；","")) | N31: =IF(A31="","",COUNTIF(Samples[樣品編號],A31))
A32: BH03-S_20260415_01 | B32: BH03-S | C32: 46127 | D32: Campaign 2 | E32: 0.5 | F32: 0 | G32: 1 | H32: 其他 | I32: 合成範例 | J32: 合成範例 | K32: 合成資料；來源 examples/demo/samples.csv；BH03-soil-2-1 | L32: =IF(B32="","",IF(COUNTIF(DB_03[監測點],B32)=1,INDEX(DB_03[預設介質],MATCH(B32,DB_03[監測點],0)),"")) | M32: =IF(COUNTA(A32:K32)=0,"",IF(A32="","缺樣品編號；","")&IF(AND(A32<>"",N32>1),"樣品編號重複；","")&IF(COUNTIFS(DB_03[監測點],B32,DB_03[預設介質],L32,DB_03[啟用],"是")<>1,"點位或介質待核；","")&IF(NOT(ISNUMBER(C32)),"缺採樣日期；","")&IF(AND(L32="土壤",OR(NOT(ISNUMBER(F32)),NOT(ISNUMBER(G32)))),"缺土壤深度；","")&IF(AND(L32="土壤",ISNUMBER(F32),ISNUMBER(G32),OR(F32>G32,F32<0)),"土壤深度起迄錯誤；","")&IF(AND(L32="地下水",F32<>"",NOT(ISNUMBER(F32))),"水位須為數值；","")&IF(AND(L32="地下水",H32=""),"缺採樣方法；","")&IF(AND(B32<>"",L32=""),"監測點未建或重複；","")) | N32: =IF(A32="","",COUNTIF(Samples[樣品編號],A32))
A33: BH03-W_20260415_01 | B33: BH03-W | C33: 46127 | D33: Campaign 2 | E33: 0.5 | F33: 0.2 | H33: 微洗井 | I33: 合成範例 | J33: 合成範例 | K33: 合成資料；來源 examples/demo/samples.csv；BH03-groundwater-2-1 | L33: =IF(B33="","",IF(COUNTIF(DB_03[監測點],B33)=1,INDEX(DB_03[預設介質],MATCH(B33,DB_03[監測點],0)),"")) | M33: =IF(COUNTA(A33:K33)=0,"",IF(A33="","缺樣品編號；","")&IF(AND(A33<>"",N33>1),"樣品編號重複；","")&IF(COUNTIFS(DB_03[監測點],B33,DB_03[預設介質],L33,DB_03[啟用],"是")<>1,"點位或介質待核；","")&IF(NOT(ISNUMBER(C33)),"缺採樣日期；","")&IF(AND(L33="土壤",OR(NOT(ISNUMBER(F33)),NOT(ISNUMBER(G33)))),"缺土壤深度；","")&IF(AND(L33="土壤",ISNUMBER(F33),ISNUMBER(G33),OR(F33>G33,F33<0)),"土壤深度起迄錯誤；","")&IF(AND(L33="地下水",F33<>"",NOT(ISNUMBER(F33))),"水位須為數值；","")&IF(AND(L33="地下水",H33=""),"缺採樣方法；","")&IF(AND(B33<>"",L33=""),"監測點未建或重複；","")) | N33: =IF(A33="","",COUNTIF(Samples[樣品編號],A33))
A34: BH03-S_20260415_02 | B34: BH03-S | C34: 46127 | D34: Campaign 2 | E34: 1.5 | F34: 1 | G34: 2 | H34: 其他 | I34: 合成範例 | J34: 合成範例 | K34: 合成資料；來源 examples/demo/samples.csv；BH03-soil-2-2 | L34: =IF(B34="","",IF(COUNTIF(DB_03[監測點],B34)=1,INDEX(DB_03[預設介質],MATCH(B34,DB_03[監測點],0)),"")) | M34: =IF(COUNTA(A34:K34)=0,"",IF(A34="","缺樣品編號；","")&IF(AND(A34<>"",N34>1),"樣品編號重複；","")&IF(COUNTIFS(DB_03[監測點],B34,DB_03[預設介質],L34,DB_03[啟用],"是")<>1,"點位或介質待核；","")&IF(NOT(ISNUMBER(C34)),"缺採樣日期；","")&IF(AND(L34="土壤",OR(NOT(ISNUMBER(F34)),NOT(ISNUMBER(G34)))),"缺土壤深度；","")&IF(AND(L34="土壤",ISNUMBER(F34),ISNUMBER(G34),OR(F34>G34,F34<0)),"土壤深度起迄錯誤；","")&IF(AND(L34="地下水",F34<>"",NOT(ISNUMBER(F34))),"水位須為數值；","")&IF(AND(L34="地下水",H34=""),"缺採樣方法；","")&IF(AND(B34<>"",L34=""),"監測點未建或重複；","")) | N34: =IF(A34="","",COUNTIF(Samples[樣品編號],A34))
A35: BH03-W_20260415_02 | B35: BH03-W | C35: 46127 | D35: Campaign 2 | E35: 1.5 | H35: 微洗井 | I35: 合成範例 | J35: 合成範例 | K35: 合成資料；來源 examples/demo/samples.csv；BH03-groundwater-2-2 | L35: =IF(B35="","",IF(COUNTIF(DB_03[監測點],B35)=1,INDEX(DB_03[預設介質],MATCH(B35,DB_03[監測點],0)),"")) | M35: =IF(COUNTA(A35:K35)=0,"",IF(A35="","缺樣品編號；","")&IF(AND(A35<>"",N35>1),"樣品編號重複；","")&IF(COUNTIFS(DB_03[監測點],B35,DB_03[預設介質],L35,DB_03[啟用],"是")<>1,"點位或介質待核；","")&IF(NOT(ISNUMBER(C35)),"缺採樣日期；","")&IF(AND(L35="土壤",OR(NOT(ISNUMBER(F35)),NOT(ISNUMBER(G35)))),"缺土壤深度；","")&IF(AND(L35="土壤",ISNUMBER(F35),ISNUMBER(G35),OR(F35>G35,F35<0)),"土壤深度起迄錯誤；","")&IF(AND(L35="地下水",F35<>"",NOT(ISNUMBER(F35))),"水位須為數值；","")&IF(AND(L35="地下水",H35=""),"缺採樣方法；","")&IF(AND(B35<>"",L35=""),"監測點未建或重複；","")) | N35: =IF(A35="","",COUNTIF(Samples[樣品編號],A35))
A36: BH03-S_20260415_03 | B36: BH03-S | C36: 46127 | D36: Campaign 2 | E36: 2.5 | F36: 2 | G36: 3 | H36: 其他 | I36: 合成範例 | J36: 合成範例 | K36: 合成資料；來源 examples/demo/samples.csv；BH03-soil-2-3 | L36: =IF(B36="","",IF(COUNTIF(DB_03[監測點],B36)=1,INDEX(DB_03[預設介質],MATCH(B36,DB_03[監測點],0)),"")) | M36: =IF(COUNTA(A36:K36)=0,"",IF(A36="","缺樣品編號；","")&IF(AND(A36<>"",N36>1),"樣品編號重複；","")&IF(COUNTIFS(DB_03[監測點],B36,DB_03[預設介質],L36,DB_03[啟用],"是")<>1,"點位或介質待核；","")&IF(NOT(ISNUMBER(C36)),"缺採樣日期；","")&IF(AND(L36="土壤",OR(NOT(ISNUMBER(F36)),NOT(ISNUMBER(G36)))),"缺土壤深度；","")&IF(AND(L36="土壤",ISNUMBER(F36),ISNUMBER(G36),OR(F36>G36,F36<0)),"土壤深度起迄錯誤；","")&IF(AND(L36="地下水",F36<>"",NOT(ISNUMBER(F36))),"水位須為數值；","")&IF(AND(L36="地下水",H36=""),"缺採樣方法；","")&IF(AND(B36<>"",L36=""),"監測點未建或重複；","")) | N36: =IF(A36="","",COUNTIF(Samples[樣品編號],A36))
A37: BH03-W_20260415_03 | B37: BH03-W | C37: 46127 | D37: Campaign 2 | E37: 2.5 | H37: 微洗井 | I37: 合成範例 | J37: 合成範例 | K37: 合成資料；來源 examples/demo/samples.csv；BH03-groundwater-2-3 | L37: =IF(B37="","",IF(COUNTIF(DB_03[監測點],B37)=1,INDEX(DB_03[預設介質],MATCH(B37,DB_03[監測點],0)),"")) | M37: =IF(COUNTA(A37:K37)=0,"",IF(A37="","缺樣品編號；","")&IF(AND(A37<>"",N37>1),"樣品編號重複；","")&IF(COUNTIFS(DB_03[監測點],B37,DB_03[預設介質],L37,DB_03[啟用],"是")<>1,"點位或介質待核；","")&IF(NOT(ISNUMBER(C37)),"缺採樣日期；","")&IF(AND(L37="土壤",OR(NOT(ISNUMBER(F37)),NOT(ISNUMBER(G37)))),"缺土壤深度；","")&IF(AND(L37="土壤",ISNUMBER(F37),ISNUMBER(G37),OR(F37>G37,F37<0)),"土壤深度起迄錯誤；","")&IF(AND(L37="地下水",F37<>"",NOT(ISNUMBER(F37))),"水位須為數值；","")&IF(AND(L37="地下水",H37=""),"缺採樣方法；","")&IF(AND(B37<>"",L37=""),"監測點未建或重複；","")) | N37: =IF(A37="","",COUNTIF(Samples[樣品編號],A37))
A38: BH04-S_20260115_01 | B38: BH04-S | C38: 46037 | D38: Campaign 1 | E38: 0.5 | F38: 0 | G38: 1 | H38: 其他 | I38: 合成範例 | J38: 合成範例 | K38: 合成資料；來源 examples/demo/samples.csv；BH04-soil-1-1 | L38: =IF(B38="","",IF(COUNTIF(DB_03[監測點],B38)=1,INDEX(DB_03[預設介質],MATCH(B38,DB_03[監測點],0)),"")) | M38: =IF(COUNTA(A38:K38)=0,"",IF(A38="","缺樣品編號；","")&IF(AND(A38<>"",N38>1),"樣品編號重複；","")&IF(COUNTIFS(DB_03[監測點],B38,DB_03[預設介質],L38,DB_03[啟用],"是")<>1,"點位或介質待核；","")&IF(NOT(ISNUMBER(C38)),"缺採樣日期；","")&IF(AND(L38="土壤",OR(NOT(ISNUMBER(F38)),NOT(ISNUMBER(G38)))),"缺土壤深度；","")&IF(AND(L38="土壤",ISNUMBER(F38),ISNUMBER(G38),OR(F38>G38,F38<0)),"土壤深度起迄錯誤；","")&IF(AND(L38="地下水",F38<>"",NOT(ISNUMBER(F38))),"水位須為數值；","")&IF(AND(L38="地下水",H38=""),"缺採樣方法；","")&IF(AND(B38<>"",L38=""),"監測點未建或重複；","")) | N38: =IF(A38="","",COUNTIF(Samples[樣品編號],A38))
A39: BH04-W_20260115_01 | B39: BH04-W | C39: 46037 | D39: Campaign 1 | E39: 0.5 | F39: 0.2 | H39: 微洗井 | I39: 合成範例 | J39: 合成範例 | K39: 合成資料；來源 examples/demo/samples.csv；BH04-groundwater-1-1 | L39: =IF(B39="","",IF(COUNTIF(DB_03[監測點],B39)=1,INDEX(DB_03[預設介質],MATCH(B39,DB_03[監測點],0)),"")) | M39: =IF(COUNTA(A39:K39)=0,"",IF(A39="","缺樣品編號；","")&IF(AND(A39<>"",N39>1),"樣品編號重複；","")&IF(COUNTIFS(DB_03[監測點],B39,DB_03[預設介質],L39,DB_03[啟用],"是")<>1,"點位或介質待核；","")&IF(NOT(ISNUMBER(C39)),"缺採樣日期；","")&IF(AND(L39="土壤",OR(NOT(ISNUMBER(F39)),NOT(ISNUMBER(G39)))),"缺土壤深度；","")&IF(AND(L39="土壤",ISNUMBER(F39),ISNUMBER(G39),OR(F39>G39,F39<0)),"土壤深度起迄錯誤；","")&IF(AND(L39="地下水",F39<>"",NOT(ISNUMBER(F39))),"水位須為數值；","")&IF(AND(L39="地下水",H39=""),"缺採樣方法；","")&IF(AND(B39<>"",L39=""),"監測點未建或重複；","")) | N39: =IF(A39="","",COUNTIF(Samples[樣品編號],A39))
A40: BH04-S_20260115_02 | B40: BH04-S | C40: 46037 | D40: Campaign 1 | E40: 1.5 | F40: 1 | G40: 2 | H40: 其他 | I40: 合成範例 | J40: 合成範例 | K40: 合成資料；來源 examples/demo/samples.csv；BH04-soil-1-2 | L40: =IF(B40="","",IF(COUNTIF(DB_03[監測點],B40)=1,INDEX(DB_03[預設介質],MATCH(B40,DB_03[監測點],0)),"")) | M40: =IF(COUNTA(A40:K40)=0,"",IF(A40="","缺樣品編號；","")&IF(AND(A40<>"",N40>1),"樣品編號重複；","")&IF(COUNTIFS(DB_03[監測點],B40,DB_03[預設介質],L40,DB_03[啟用],"是")<>1,"點位或介質待核；","")&IF(NOT(ISNUMBER(C40)),"缺採樣日期；","")&IF(AND(L40="土壤",OR(NOT(ISNUMBER(F40)),NOT(ISNUMBER(G40)))),"缺土壤深度；","")&IF(AND(L40="土壤",ISNUMBER(F40),ISNUMBER(G40),OR(F40>G40,F40<0)),"土壤深度起迄錯誤；","")&IF(AND(L40="地下水",F40<>"",NOT(ISNUMBER(F40))),"水位須為數值；","")&IF(AND(L40="地下水",H40=""),"缺採樣方法；","")&IF(AND(B40<>"",L40=""),"監測點未建或重複；","")) | N40: =IF(A40="","",COUNTIF(Samples[樣品編號],A40))
...

Sheet 02_分析資料庫
A1: 分析項目 | B1: 原始值 | C1: 結果單位 | D1: 備註 | E1: 監測點 | F1: 採樣日期 | G1: 解析值 | H1: 關聯鍵 | I1: 樣品索引 | J1: 介質 | K1: 標準單位 | L1: 換算係數 | M1: 正規字串 | N1: 限定符 | O1: 數字段 | P1: 原始數值或界限 | Q1: 原始值(標準單位) | R1: 管制設定值 | S1: 監測設定值 | T1: 測項索引 | U1: 標準索引 | V1: 測項鍵 | W1: 標準鍵 | X1: 結果識別鍵 | Y1: 樣品檢查 | Z1: 格式檢查 | AA1: 重複檢查 | AB1: 單位檢查 | AC1: 標準檢查 | AD1: 管制比較 | AE1: 監測比較 | AF1: 完整性檢查 | AG1: 解析規則 | AH1: 原始轉值 | AI1: 樣品位置
A2: 鋅 | B2: 74 | C2: mg/kg | D2: 合成資料，非實測；method=XRF; basis=dry | E2: =IF(OR(I2="",I2=0),"",IF(INDEX(Samples[監測點],I2)="","",INDEX(Samples[監測點],I2))) | F2: =IF(OR(I2="",I2=0),"",IF(INDEX(Samples[採樣日期],I2)="","",INDEX(Samples[採樣日期],I2))) | G2: =IF(OR(M2="",M2="NA",M2="N/A"),"",IF(OR(M2="ND",M2="N.D."),0,IFERROR(IF(OR(OR(ISNUMBER(SEARCH("%",O2)),ISNUMBER(SEARCH(" ",O2)),ISNUMBER(SEARCH(",",O2))),OR(SUBSTITUTE(SUBSTITUTE(SUBSTITUTE(SUBSTITUTE(SUBSTITUTE(SUBSTITUTE(SUBSTITUTE(SUBSTITUTE(SUBSTITUTE(SUBSTITUTE(SUBSTITUTE(SUBSTITUTE(SUBSTITUTE(SUBSTITUTE(SUBSTITUTE(SUBSTITUTE(SUBSTITUTE(SUBSTITUTE("x"&M2,"0",""),"1",""),"2",""),"3",""),"4",""),"5",""),"6",""),"7",""),"8",""),"9",""),".",""),"E",""),"+",""),"-",""),"<",""),">",""),"=","")," ","")<>"x",ISNUMBER(SEARCH("-",SUBSTITUTE(SUBSTITUTE("x"&MID(M2,2,99),"E-","E"),"E+","E"))),ISNUMBER(SEARCH("+",SUBSTITUTE(SUBSTITUTE("x"&MID(M2,2,99),"E-","E"),"E+","E"))))),"",IF(AND(OR(LEFT(M2,1)="<",LEFT(M2,1)=">"),IF(O2="",0,IF(ISNUMBER(AH2),AH2,NA()))<0),"",IF(O2="",0,IF(ISNUMBER(AH2),AH2,NA()))/IF(LEFT(M2,1)="<",2,1))),""))) | H2: BH01-S_20260115_01 | I2: =IF(OR(H2="",AI2=0),0,IF(INDEX(Samples[樣品重複筆數],AI2)=1,AI2,0)) | J2: =IF(OR(COUNTA($A2:$D2)=0,I2=0),"",IF(INDEX(Samples[介質],I2)="","",INDEX(Samples[介質],I2))) | K2: =IF(OR(COUNTA($A2:$D2)=0,T2=0),"",IF(INDEX(DB_04[標準單位],T2)="","",INDEX(DB_04[標準單位],T2))) | L2: =IF(COUNTA($A2:$D2)=0,"",IF(OR(C2="",K2=""),"",IF(C2=K2,1,IF(COUNTIFS(DB_06[換算鍵],C2&"|"&K2,DB_06[換算檢查],"OK")=1,INDEX(DB_06[乘數],MATCH(C2&"|"&K2,DB_06[換算鍵],0)),"")))) | M2: =UPPER(SUBSTITUTE(SUBSTITUTE(SUBSTITUTE(SUBSTITUTE(TRIM(B2&""),"＜","<"),"＞",">"),"≤","<="),"≥",">=")) | N2: =IF(M2="","",IF(OR(M2="ND",M2="N.D."),"ND",IF(OR(M2="NA",M2="N/A",M2="N.A."),"NA",IF(OR(LEFT(M2,2)="<=",LEFT(M2,2)=">="),LEFT(M2,2),IF(OR(LEFT(M2,1)="<",LEFT(M2,1)=">"),LEFT(M2,1),"數值"))))) | O2: =IF(OR(N2="",N2="ND",N2="NA"),"",IF(N2="數值",M2,TRIM(MID(M2,LEN(N2)+1,99)))) | P2: =IF(O2="","",IFERROR(IF(OR(OR(ISNUMBER(SEARCH("%",O2)),ISNUMBER(SEARCH(" ",O2)),ISNUMBER(SEARCH(",",O2))),OR(SUBSTITUTE(SUBSTITUTE(SUBSTITUTE(SUBSTITUTE(SUBSTITUTE(SUBSTITUTE(SUBSTITUTE(SUBSTITUTE(SUBSTITUTE(SUBSTITUTE(SUBSTITUTE(SUBSTITUTE(SUBSTITUTE(SUBSTITUTE(SUBSTITUTE(SUBSTITUTE(SUBSTITUTE(SUBSTITUTE("x"&O2,"0",""),"1",""),"2",""),"3",""),"4",""),"5",""),"6",""),"7",""),"8",""),"9",""),".",""),"E",""),"+",""),"-",""),"<",""),">",""),"=","")," ","")<>"x",ISNUMBER(SEARCH("-",SUBSTITUTE(SUBSTITUTE("x"&MID(O2,2,99),"E-","E"),"E+","E"))),ISNUMBER(SEARCH("+",SUBSTITUTE(SUBSTITUTE("x"&MID(O2,2,99),"E-","E"),"E+","E"))))),"",IF(ISNUMBER(AH2),AH2,NA())),"")) | Q2: =IF(AND(ISNUMBER(L2),ISNUMBER(P2)),L2*P2,"") | R2: =IF(OR(COUNTA($A2:$D2)=0,U2=0),"",IF(INDEX(DB_05[管制設定值],U2)="","",INDEX(DB_05[管制設定值],U2))) | S2: =IF(OR(COUNTA($A2:$D2)=0,U2=0),"",IF(INDEX(DB_05[監測設定值],U2)="","",INDEX(DB_05[監測設定值],U2))) | T2: =IF(COUNTA($A2:$D2)=0,"",IF(COUNTIFS(DB_04[測項鍵],V2)=1,MATCH(V2,DB_04[測項鍵],0),0)) | U2: =IF(COUNTA($A2:$D2)=0,"",IF(COUNTIFS(DB_05[標準鍵],W2)=1,MATCH(W2,DB_05[標準鍵],0),0)) | V2: =IF(OR(J2="",A2=""),"",J2&"|"&A2) | W2: =IF(OR('07_QAQC'!$C$3="",V2=""),"",'07_QAQC'!$C$3&"|"&V2) | X2: =IF(OR(H2="",A2=""),"",LEN(H2)&":"&H2&LEN(A2)&":"&A2) | Y2: =IF(COUNTA($A2:$D2)=0,"",IF(I2=0,"樣品未建或重複",IF(INDEX(Samples[樣品檢查],I2)="","OK",INDEX(Samples[樣品檢查],I2)))) | Z2: =IF(COUNTA($A2:$D2)=0,"",IF(B2="","缺原始值",IF(OR(B2="-",B2="--"),"無資料",IF(N2="NA","不適用",IF(N2="ND","OK",IF(NOT(ISNUMBER(P2)),"格式待核",IF(AND(N2<>"數值",P2<0),"界限不得為負","OK"))))))) | AA2: =IF(COUNTA(A2:D2)=0,"",IF(OR(A2="",H2=""),"缺識別欄位",IF(IF(LEN("="&SUBSTITUTE(SUBSTITUTE(SUBSTITUTE(X2,"~","~~"),"*","~*"),"?","~?"))<=255,COUNTIF(Results[結果識別鍵],"="&SUBSTITUTE(SUBSTITUTE(SUBSTITUTE(X2,"~","~~"),"*","~*"),"?","~?")),COUNTIFS(Results[關聯鍵],"="&SUBSTITUTE(SUBSTITUTE(SUBSTITUTE(H2,"~","~~"),"*","~*"),"?","~?"),Results[分析項目],"="&SUBSTITUTE(SUBSTITUTE(SUBSTITUTE(A2,"~","~~"),"*","~*"),"?","~?")))>1,"同關聯鍵測項重複","OK"))) | AB2: =IF(COUNTA($A2:$D2)=0,"",IF(OR(C2="",K2=""),"缺單位",IF(NOT(ISNUMBER(L2)),"單位不相容",IF(L2=1,"OK","已換算")))) | AC2: =IF(COUNTA($A2:$D2)=0,"",IF('07_QAQC'!$C$3="","未選比較版本",IF(U2=0,IF(COUNTIFS(DB_05[標準鍵],W2)>1,"標準鍵重複","未訂此介質／測項門檻"),IF(INDEX(DB_05[版本檢查],U2)<>"OK","標準主檔待核",IF(INDEX(DB_05[標準單位],U2)<>K2,"標準單位不符",IF(INDEX(DB_05[核對狀態],U2)="停用","停用",IF(F2="","缺採樣日期",IF(OR(AND(INDEX(DB_05[生效日],U2)<>"",F2<INDEX(DB_05[生效日],U2)),AND(INDEX(DB_05[失效日],U2)<>"",F2>INDEX(DB_05[失效日],U2))),"日期不適用",INDEX(DB_05[核對狀態],U2))))))))) | AD2: =IF(COUNTA($A2:$D2)=0,"",IF(AC2="未訂此介質／測項門檻",AC2,IF(AC2<>"已核對","標準待核",IF(R2="","未訂管制值",IF(NOT(ISNUMBER(L2)),"單位待核",IF(N2="ND","無法判定（ND無界限）",IF(N2="NA","不適用",IF(Z2<>"OK",Z2,IF(N2="數值",IF(Q2>=R2,"達管制值","未達管制值"),IF(OR(N2="<",N2="<="),IF(OR(Q2<R2,AND(N2="<",Q2=R2)),"未達管制值","無法判定"),IF(OR(N2=">",N2=">="),IF(Q2>=R2,"達管制值","無法判定"),"格式待核"))))))))))) | AE2: =IF(COUNTA($A2:$D2)=0,"",IF(AC2="未訂此介質／測項門檻",AC2,IF(AC2<>"已核對","標準待核",IF(S2="","未訂監測值",IF(NOT(ISNUMBER(L2)),"單位待核",IF(N2="ND","無法判定（ND無界限）",IF(N2="NA","不適用",IF(Z2<>"OK",Z2,IF(N2="數值",IF(Q2>=S2,"達監測值","未達監測值"),IF(OR(N2="<",N2="<="),IF(OR(Q2<S2,AND(N2="<",Q2=S2)),"未達監測值","無法判定"),IF(OR(N2=">",N2=">="),IF(Q2>=S2,"達監測值","無法判定"),"格式待核"))))))))))) | AF2: =IF(COUNTA($A2:$D2)=0,"",IF(OR(E2="",A2="",B2="",C2=""),"缺必要欄位",IF(Y2<>"OK","樣品資料待補",IF(T2=0,"測項未建或重複",IF(INDEX(DB_04[啟用],T2)<>"是","測項停用",IF(AND(Z2<>"OK",Z2<>"不適用"),Z2,IF(AND(AB2<>"OK",AB2<>"已換算"),"單位待核",IF(AA2<>"OK",AA2,"OK")))))))) | AG2: =IF(COUNTA($A2:$D2)=0,"",IF(N2="ND","ND取0",IF(OR(N2="<",N2="<="),"界限除以2",IF(N2="NA","不適用",IF(OR(N2=">",N2=">="),"保留界限數值","保留原數值"))))) | AH2: =IF(O2="","",IFERROR(_xlfn.NUMBERVALUE(O2,".",","),"")) | AI2: =IF(H2="","",IFERROR(MATCH(H2,Samples[樣品編號],0),0))
A3: 總有機碳 | B3: 0.26 | C3: % | D3: 合成資料，非實測；method=lab; basis=dry | E3: =IF(OR(I3="",I3=0),"",IF(INDEX(Samples[監測點],I3)="","",INDEX(Samples[監測點],I3))) | F3: =IF(OR(I3="",I3=0),"",IF(INDEX(Samples[採樣日期],I3)="","",INDEX(Samples[採樣日期],I3))) | G3: =IF(OR(M3="",M3="NA",M3="N/A"),"",IF(OR(M3="ND",M3="N.D."),0,IFERROR(IF(OR(OR(ISNUMBER(SEARCH("%",O3)),ISNUMBER(SEARCH(" ",O3)),ISNUMBER(SEARCH(",",O3))),OR(SUBSTITUTE(SUBSTITUTE(SUBSTITUTE(SUBSTITUTE(SUBSTITUTE(SUBSTITUTE(SUBSTITUTE(SUBSTITUTE(SUBSTITUTE(SUBSTITUTE(SUBSTITUTE(SUBSTITUTE(SUBSTITUTE(SUBSTITUTE(SUBSTITUTE(SUBSTITUTE(SUBSTITUTE(SUBSTITUTE("x"&M3,"0",""),"1",""),"2",""),"3",""),"4",""),"5",""),"6",""),"7",""),"8",""),"9",""),".",""),"E",""),"+",""),"-",""),"<",""),">",""),"=","")," ","")<>"x",ISNUMBER(SEARCH("-",SUBSTITUTE(SUBSTITUTE("x"&MID(M3,2,99),"E-","E"),"E+","E"))),ISNUMBER(SEARCH("+",SUBSTITUTE(SUBSTITUTE("x"&MID(M3,2,99),"E-","E"),"E+","E"))))),"",IF(AND(OR(LEFT(M3,1)="<",LEFT(M3,1)=">"),IF(O3="",0,IF(ISNUMBER(AH3),AH3,NA()))<0),"",IF(O3="",0,IF(ISNUMBER(AH3),AH3,NA()))/IF(LEFT(M3,1)="<",2,1))),""))) | H3: BH01-S_20260115_01 | I3: =IF(OR(H3="",AI3=0),0,IF(INDEX(Samples[樣品重複筆數],AI3)=1,AI3,0)) | J3: =IF(OR(COUNTA($A3:$D3)=0,I3=0),"",IF(INDEX(Samples[介質],I3)="","",INDEX(Samples[介質],I3))) | K3: =IF(OR(COUNTA($A3:$D3)=0,T3=0),"",IF(INDEX(DB_04[標準單位],T3)="","",INDEX(DB_04[標準單位],T3))) | L3: =IF(COUNTA($A3:$D3)=0,"",IF(OR(C3="",K3=""),"",IF(C3=K3,1,IF(COUNTIFS(DB_06[換算鍵],C3&"|"&K3,DB_06[換算檢查],"OK")=1,INDEX(DB_06[乘數],MATCH(C3&"|"&K3,DB_06[換算鍵],0)),"")))) | M3: =UPPER(SUBSTITUTE(SUBSTITUTE(SUBSTITUTE(SUBSTITUTE(TRIM(B3&""),"＜","<"),"＞",">"),"≤","<="),"≥",">=")) | N3: =IF(M3="","",IF(OR(M3="ND",M3="N.D."),"ND",IF(OR(M3="NA",M3="N/A",M3="N.A."),"NA",IF(OR(LEFT(M3,2)="<=",LEFT(M3,2)=">="),LEFT(M3,2),IF(OR(LEFT(M3,1)="<",LEFT(M3,1)=">"),LEFT(M3,1),"數值"))))) | O3: =IF(OR(N3="",N3="ND",N3="NA"),"",IF(N3="數值",M3,TRIM(MID(M3,LEN(N3)+1,99)))) | P3: =IF(O3="","",IFERROR(IF(OR(OR(ISNUMBER(SEARCH("%",O3)),ISNUMBER(SEARCH(" ",O3)),ISNUMBER(SEARCH(",",O3))),OR(SUBSTITUTE(SUBSTITUTE(SUBSTITUTE(SUBSTITUTE(SUBSTITUTE(SUBSTITUTE(SUBSTITUTE(SUBSTITUTE(SUBSTITUTE(SUBSTITUTE(SUBSTITUTE(SUBSTITUTE(SUBSTITUTE(SUBSTITUTE(SUBSTITUTE(SUBSTITUTE(SUBSTITUTE(SUBSTITUTE("x"&O3,"0",""),"1",""),"2",""),"3",""),"4",""),"5",""),"6",""),"7",""),"8",""),"9",""),".",""),"E",""),"+",""),"-",""),"<",""),">",""),"=","")," ","")<>"x",ISNUMBER(SEARCH("-",SUBSTITUTE(SUBSTITUTE("x"&MID(O3,2,99),"E-","E"),"E+","E"))),ISNUMBER(SEARCH("+",SUBSTITUTE(SUBSTITUTE("x"&MID(O3,2,99),"E-","E"),"E+","E"))))),"",IF(ISNUMBER(AH3),AH3,NA())),"")) | Q3: =IF(AND(ISNUMBER(L3),ISNUMBER(P3)),L3*P3,"") | R3: =IF(OR(COUNTA($A3:$D3)=0,U3=0),"",IF(INDEX(DB_05[管制設定值],U3)="","",INDEX(DB_05[管制設定值],U3))) | S3: =IF(OR(COUNTA($A3:$D3)=0,U3=0),"",IF(INDEX(DB_05[監測設定值],U3)="","",INDEX(DB_05[監測設定值],U3))) | T3: =IF(COUNTA($A3:$D3)=0,"",IF(COUNTIFS(DB_04[測項鍵],V3)=1,MATCH(V3,DB_04[測項鍵],0),0)) | U3: =IF(COUNTA($A3:$D3)=0,"",IF(COUNTIFS(DB_05[標準鍵],W3)=1,MATCH(W3,DB_05[標準鍵],0),0)) | V3: =IF(OR(J3="",A3=""),"",J3&"|"&A3) | W3: =IF(OR('07_QAQC'!$C$3="",V3=""),"",'07_QAQC'!$C$3&"|"&V3) | X3: =IF(OR(H3="",A3=""),"",LEN(H3)&":"&H3&LEN(A3)&":"&A3) | Y3: =IF(COUNTA($A3:$D3)=0,"",IF(I3=0,"樣品未建或重複",IF(INDEX(Samples[樣品檢查],I3)="","OK",INDEX(Samples[樣品檢查],I3)))) | Z3: =IF(COUNTA($A3:$D3)=0,"",IF(B3="","缺原始值",IF(OR(B3="-",B3="--"),"無資料",IF(N3="NA","不適用",IF(N3="ND","OK",IF(NOT(ISNUMBER(P3)),"格式待核",IF(AND(N3<>"數值",P3<0),"界限不得為負","OK"))))))) | AA3: =IF(COUNTA(A3:D3)=0,"",IF(OR(A3="",H3=""),"缺識別欄位",IF(IF(LEN("="&SUBSTITUTE(SUBSTITUTE(SUBSTITUTE(X3,"~","~~"),"*","~*"),"?","~?"))<=255,COUNTIF(Results[結果識別鍵],"="&SUBSTITUTE(SUBSTITUTE(SUBSTITUTE(X3,"~","~~"),"*","~*"),"?","~?")),COUNTIFS(Results[關聯鍵],"="&SUBSTITUTE(SUBSTITUTE(SUBSTITUTE(H3,"~","~~"),"*","~*"),"?","~?"),Results[分析項目],"="&SUBSTITUTE(SUBSTITUTE(SUBSTITUTE(A3,"~","~~"),"*","~*"),"?","~?")))>1,"同關聯鍵測項重複","OK"))) | AB3: =IF(COUNTA($A3:$D3)=0,"",IF(OR(C3="",K3=""),"缺單位",IF(NOT(ISNUMBER(L3)),"單位不相容",IF(L3=1,"OK","已換算")))) | AC3: =IF(COUNTA($A3:$D3)=0,"",IF('07_QAQC'!$C$3="","未選比較版本",IF(U3=0,IF(COUNTIFS(DB_05[標準鍵],W3)>1,"標準鍵重複","未訂此介質／測項門檻"),IF(INDEX(DB_05[版本檢查],U3)<>"OK","標準主檔待核",IF(INDEX(DB_05[標準單位],U3)<>K3,"標準單位不符",IF(INDEX(DB_05[核對狀態],U3)="停用","停用",IF(F3="","缺採樣日期",IF(OR(AND(INDEX(DB_05[生效日],U3)<>"",F3<INDEX(DB_05[生效日],U3)),AND(INDEX(DB_05[失效日],U3)<>"",F3>INDEX(DB_05[失效日],U3))),"日期不適用",INDEX(DB_05[核對狀態],U3))))))))) | AD3: =IF(COUNTA($A3:$D3)=0,"",IF(AC3="未訂此介質／測項門檻",AC3,IF(AC3<>"已核對","標準待核",IF(R3="","未訂管制值",IF(NOT(ISNUMBER(L3)),"單位待核",IF(N3="ND","無法判定（ND無界限）",IF(N3="NA","不適用",IF(Z3<>"OK",Z3,IF(N3="數值",IF(Q3>=R3,"達管制值","未達管制值"),IF(OR(N3="<",N3="<="),IF(OR(Q3<R3,AND(N3="<",Q3=R3)),"未達管制值","無法判定"),IF(OR(N3=">",N3=">="),IF(Q3>=R3,"達管制值","無法判定"),"格式待核"))))))))))) | AE3: =IF(COUNTA($A3:$D3)=0,"",IF(AC3="未訂此介質／測項門檻",AC3,IF(AC3<>"已核對","標準待核",IF(S3="","未訂監測值",IF(NOT(ISNUMBER(L3)),"單位待核",IF(N3="ND","無法判定（ND無界限）",IF(N3="NA","不適用",IF(Z3<>"OK",Z3,IF(N3="數值",IF(Q3>=S3,"達監測值","未達監測值"),IF(OR(N3="<",N3="<="),IF(OR(Q3<S3,AND(N3="<",Q3=S3)),"未達監測值","無法判定"),IF(OR(N3=">",N3=">="),IF(Q3>=S3,"達監測值","無法判定"),"格式待核"))))))))))) | AF3: =IF(COUNTA($A3:$D3)=0,"",IF(OR(E3="",A3="",B3="",C3=""),"缺必要欄位",IF(Y3<>"OK","樣品資料待補",IF(T3=0,"測項未建或重複",IF(INDEX(DB_04[啟用],T3)<>"是","測項停用",IF(AND(Z3<>"OK",Z3<>"不適用"),Z3,IF(AND(AB3<>"OK",AB3<>"已換算"),"單位待核",IF(AA3<>"OK",AA3,"OK")))))))) | AG3: =IF(COUNTA($A3:$D3)=0,"",IF(N3="ND","ND取0",IF(OR(N3="<",N3="<="),"界限除以2",IF(N3="NA","不適用",IF(OR(N3=">",N3=">="),"保留界限數值","保留原數值"))))) | AH3: =IF(O3="","",IFERROR(_xlfn.NUMBERVALUE(O3,".",","),"")) | AI3: =IF(H3="","",IFERROR(MATCH(H3,Samples[樣品編號],0),0))
A4: pH | B4: 6.49 | C4: 無因次 | D4: 合成資料，非實測；method=field | E4: =IF(OR(I4="",I4=0),"",IF(INDEX(Samples[監測點],I4)="","",INDEX(Samples[監測點],I4))) | F4: =IF(OR(I4="",I4=0),"",IF(INDEX(Samples[採樣日期],I4)="","",INDEX(Samples[採樣日期],I4))) | G4: =IF(OR(M4="",M4="NA",M4="N/A"),"",IF(OR(M4="ND",M4="N.D."),0,IFERROR(IF(OR(OR(ISNUMBER(SEARCH("%",O4)),ISNUMBER(SEARCH(" ",O4)),ISNUMBER(SEARCH(",",O4))),OR(SUBSTITUTE(SUBSTITUTE(SUBSTITUTE(SUBSTITUTE(SUBSTITUTE(SUBSTITUTE(SUBSTITUTE(SUBSTITUTE(SUBSTITUTE(SUBSTITUTE(SUBSTITUTE(SUBSTITUTE(SUBSTITUTE(SUBSTITUTE(SUBSTITUTE(SUBSTITUTE(SUBSTITUTE(SUBSTITUTE("x"&M4,"0",""),"1",""),"2",""),"3",""),"4",""),"5",""),"6",""),"7",""),"8",""),"9",""),".",""),"E",""),"+",""),"-",""),"<",""),">",""),"=","")," ","")<>"x",ISNUMBER(SEARCH("-",SUBSTITUTE(SUBSTITUTE("x"&MID(M4,2,99),"E-","E"),"E+","E"))),ISNUMBER(SEARCH("+",SUBSTITUTE(SUBSTITUTE("x"&MID(M4,2,99),"E-","E"),"E+","E"))))),"",IF(AND(OR(LEFT(M4,1)="<",LEFT(M4,1)=">"),IF(O4="",0,IF(ISNUMBER(AH4),AH4,NA()))<0),"",IF(O4="",0,IF(ISNUMBER(AH4),AH4,NA()))/IF(LEFT(M4,1)="<",2,1))),""))) | H4: BH01-W_20260115_01 | I4: =IF(OR(H4="",AI4=0),0,IF(INDEX(Samples[樣品重複筆數],AI4)=1,AI4,0)) | J4: =IF(OR(COUNTA($A4:$D4)=0,I4=0),"",IF(INDEX(Samples[介質],I4)="","",INDEX(Samples[介質],I4))) | K4: =IF(OR(COUNTA($A4:$D4)=0,T4=0),"",IF(INDEX(DB_04[標準單位],T4)="","",INDEX(DB_04[標準單位],T4))) | L4: =IF(COUNTA($A4:$D4)=0,"",IF(OR(C4="",K4=""),"",IF(C4=K4,1,IF(COUNTIFS(DB_06[換算鍵],C4&"|"&K4,DB_06[換算檢查],"OK")=1,INDEX(DB_06[乘數],MATCH(C4&"|"&K4,DB_06[換算鍵],0)),"")))) | M4: =UPPER(SUBSTITUTE(SUBSTITUTE(SUBSTITUTE(SUBSTITUTE(TRIM(B4&""),"＜","<"),"＞",">"),"≤","<="),"≥",">=")) | N4: =IF(M4="","",IF(OR(M4="ND",M4="N.D."),"ND",IF(OR(M4="NA",M4="N/A",M4="N.A."),"NA",IF(OR(LEFT(M4,2)="<=",LEFT(M4,2)=">="),LEFT(M4,2),IF(OR(LEFT(M4,1)="<",LEFT(M4,1)=">"),LEFT(M4,1),"數值"))))) | O4: =IF(OR(N4="",N4="ND",N4="NA"),"",IF(N4="數值",M4,TRIM(MID(M4,LEN(N4)+1,99)))) | P4: =IF(O4="","",IFERROR(IF(OR(OR(ISNUMBER(SEARCH("%",O4)),ISNUMBER(SEARCH(" ",O4)),ISNUMBER(SEARCH(",",O4))),OR(SUBSTITUTE(SUBSTITUTE(SUBSTITUTE(SUBSTITUTE(SUBSTITUTE(SUBSTITUTE(SUBSTITUTE(SUBSTITUTE(SUBSTITUTE(SUBSTITUTE(SUBSTITUTE(SUBSTITUTE(SUBSTITUTE(SUBSTITUTE(SUBSTITUTE(SUBSTITUTE(SUBSTITUTE(SUBSTITUTE("x"&O4,"0",""),"1",""),"2",""),"3",""),"4",""),"5",""),"6",""),"7",""),"8",""),"9",""),".",""),"E",""),"+",""),"-",""),"<",""),">",""),"=","")," ","")<>"x",ISNUMBER(SEARCH("-",SUBSTITUTE(SUBSTITUTE("x"&MID(O4,2,99),"E-","E"),"E+","E"))),ISNUMBER(SEARCH("+",SUBSTITUTE(SUBSTITUTE("x"&MID(O4,2,99),"E-","E"),"E+","E"))))),"",IF(ISNUMBER(AH4),AH4,NA())),"")) | Q4: =IF(AND(ISNUMBER(L4),ISNUMBER(P4)),L4*P4,"") | R4: =IF(OR(COUNTA($A4:$D4)=0,U4=0),"",IF(INDEX(DB_05[管制設定值],U4)="","",INDEX(DB_05[管制設定值],U4))) | S4: =IF(OR(COUNTA($A4:$D4)=0,U4=0),"",IF(INDEX(DB_05[監測設定值],U4)="","",INDEX(DB_05[監測設定值],U4))) | T4: =IF(COUNTA($A4:$D4)=0,"",IF(COUNTIFS(DB_04[測項鍵],V4)=1,MATCH(V4,DB_04[測項鍵],0),0)) | U4: =IF(COUNTA($A4:$D4)=0,"",IF(COUNTIFS(DB_05[標準鍵],W4)=1,MATCH(W4,DB_05[標準鍵],0),0)) | V4: =IF(OR(J4="",A4=""),"",J4&"|"&A4) | W4: =IF(OR('07_QAQC'!$C$3="",V4=""),"",'07_QAQC'!$C$3&"|"&V4) | X4: =IF(OR(H4="",A4=""),"",LEN(H4)&":"&H4&LEN(A4)&":"&A4) | Y4: =IF(COUNTA($A4:$D4)=0,"",IF(I4=0,"樣品未建或重複",IF(INDEX(Samples[樣品檢查],I4)="","OK",INDEX(Samples[樣品檢查],I4)))) | Z4: =IF(COUNTA($A4:$D4)=0,"",IF(B4="","缺原始值",IF(OR(B4="-",B4="--"),"無資料",IF(N4="NA","不適用",IF(N4="ND","OK",IF(NOT(ISNUMBER(P4)),"格式待核",IF(AND(N4<>"數值",P4<0),"界限不得為負","OK"))))))) | AA4: =IF(COUNTA(A4:D4)=0,"",IF(OR(A4="",H4=""),"缺識別欄位",IF(IF(LEN("="&SUBSTITUTE(SUBSTITUTE(SUBSTITUTE(X4,"~","~~"),"*","~*"),"?","~?"))<=255,COUNTIF(Results[結果識別鍵],"="&SUBSTITUTE(SUBSTITUTE(SUBSTITUTE(X4,"~","~~"),"*","~*"),"?","~?")),COUNTIFS(Results[關聯鍵],"="&SUBSTITUTE(SUBSTITUTE(SUBSTITUTE(H4,"~","~~"),"*","~*"),"?","~?"),Results[分析項目],"="&SUBSTITUTE(SUBSTITUTE(SUBSTITUTE(A4,"~","~~"),"*","~*"),"?","~?")))>1,"同關聯鍵測項重複","OK"))) | AB4: =IF(COUNTA($A4:$D4)=0,"",IF(OR(C4="",K4=""),"缺單位",IF(NOT(ISNUMBER(L4)),"單位不相容",IF(L4=1,"OK","已換算")))) | AC4: =IF(COUNTA($A4:$D4)=0,"",IF('07_QAQC'!$C$3="","未選比較版本",IF(U4=0,IF(COUNTIFS(DB_05[標準鍵],W4)>1,"標準鍵重複","未訂此介質／測項門檻"),IF(INDEX(DB_05[版本檢查],U4)<>"OK","標準主檔待核",IF(INDEX(DB_05[標準單位],U4)<>K4,"標準單位不符",IF(INDEX(DB_05[核對狀態],U4)="停用","停用",IF(F4="","缺採樣日期",IF(OR(AND(INDEX(DB_05[生效日],U4)<>"",F4<INDEX(DB_05[生效日],U4)),AND(INDEX(DB_05[失效日],U4)<>"",F4>INDEX(DB_05[失效日],U4))),"日期不適用",INDEX(DB_05[核對狀態],U4))))))))) | AD4: =IF(COUNTA($A4:$D4)=0,"",IF(AC4="未訂此介質／測項門檻",AC4,IF(AC4<>"已核對","標準待核",IF(R4="","未訂管制值",IF(NOT(ISNUMBER(L4)),"單位待核",IF(N4="ND","無法判定（ND無界限）",IF(N4="NA","不適用",IF(Z4<>"OK",Z4,IF(N4="數值",IF(Q4>=R4,"達管制值","未達管制值"),IF(OR(N4="<",N4="<="),IF(OR(Q4<R4,AND(N4="<",Q4=R4)),"未達管制值","無法判定"),IF(OR(N4=">",N4=">="),IF(Q4>=R4,"達管制值","無法判定"),"格式待核"))))))))))) | AE4: =IF(COUNTA($A4:$D4)=0,"",IF(AC4="未訂此介質／測項門檻",AC4,IF(AC4<>"已核對","標準待核",IF(S4="","未訂監測值",IF(NOT(ISNUMBER(L4)),"單位待核",IF(N4="ND","無法判定（ND無界限）",IF(N4="NA","不適用",IF(Z4<>"OK",Z4,IF(N4="數值",IF(Q4>=S4,"達監測值","未達監測值"),IF(OR(N4="<",N4="<="),IF(OR(Q4<S4,AND(N4="<",Q4=S4)),"未達監測值","無法判定"),IF(OR(N4=">",N4=">="),IF(Q4>=S4,"達監測值","無法判定"),"格式待核"))))))))))) | AF4: =IF(COUNTA($A4:$D4)=0,"",IF(OR(E4="",A4="",B4="",C4=""),"缺必要欄位",IF(Y4<>"OK","樣品資料待補",IF(T4=0,"測項未建或重複",IF(INDEX(DB_04[啟用],T4)<>"是","測項停用",IF(AND(Z4<>"OK",Z4<>"不適用"),Z4,IF(AND(AB4<>"OK",AB4<>"已換算"),"單位待核",IF(AA4<>"OK",AA4,"OK")))))))) | AG4: =IF(COUNTA($A4:$D4)=0,"",IF(N4="ND","ND取0",IF(OR(N4="<",N4="<="),"界限除以2",IF(N4="NA","不適用",IF(OR(N4=">",N4=">="),"保留界限數值","保留原數值"))))) | AH4: =IF(O4="","",IFERROR(_xlfn.NUMBERVALUE(O4,".",","),"")) | AI4: =IF(H4="","",IFERROR(MATCH(H4,Samples[樣品編號],0),0))
A5: EC | B5: 0.43 | C5: mS/cm | D5: 合成資料，非實測；method=field; temperature=25; temperature_compensated=25C; reference_temperature=25 | E5: =IF(OR(I5="",I5=0),"",IF(INDEX(Samples[監測點],I5)="","",INDEX(Samples[監測點],I5))) | F5: =IF(OR(I5="",I5=0),"",IF(INDEX(Samples[採樣日期],I5)="","",INDEX(Samples[採樣日期],I5))) | G5: =IF(OR(M5="",M5="NA",M5="N/A"),"",IF(OR(M5="ND",M5="N.D."),0,IFERROR(IF(OR(OR(ISNUMBER(SEARCH("%",O5)),ISNUMBER(SEARCH(" ",O5)),ISNUMBER(SEARCH(",",O5))),OR(SUBSTITUTE(SUBSTITUTE(SUBSTITUTE(SUBSTITUTE(SUBSTITUTE(SUBSTITUTE(SUBSTITUTE(SUBSTITUTE(SUBSTITUTE(SUBSTITUTE(SUBSTITUTE(SUBSTITUTE(SUBSTITUTE(SUBSTITUTE(SUBSTITUTE(SUBSTITUTE(SUBSTITUTE(SUBSTITUTE("x"&M5,"0",""),"1",""),"2",""),"3",""),"4",""),"5",""),"6",""),"7",""),"8",""),"9",""),".",""),"E",""),"+",""),"-",""),"<",""),">",""),"=","")," ","")<>"x",ISNUMBER(SEARCH("-",SUBSTITUTE(SUBSTITUTE("x"&MID(M5,2,99),"E-","E"),"E+","E"))),ISNUMBER(SEARCH("+",SUBSTITUTE(SUBSTITUTE("x"&MID(M5,2,99),"E-","E"),"E+","E"))))),"",IF(AND(OR(LEFT(M5,1)="<",LEFT(M5,1)=">"),IF(O5="",0,IF(ISNUMBER(AH5),AH5,NA()))<0),"",IF(O5="",0,IF(ISNUMBER(AH5),AH5,NA()))/IF(LEFT(M5,1)="<",2,1))),""))) | H5: BH01-W_20260115_01 | I5: =IF(OR(H5="",AI5=0),0,IF(INDEX(Samples[樣品重複筆數],AI5)=1,AI5,0)) | J5: =IF(OR(COUNTA($A5:$D5)=0,I5=0),"",IF(INDEX(Samples[介質],I5)="","",INDEX(Samples[介質],I5))) | K5: =IF(OR(COUNTA($A5:$D5)=0,T5=0),"",IF(INDEX(DB_04[標準單位],T5)="","",INDEX(DB_04[標準單位],T5))) | L5: =IF(COUNTA($A5:$D5)=0,"",IF(OR(C5="",K5=""),"",IF(C5=K5,1,IF(COUNTIFS(DB_06[換算鍵],C5&"|"&K5,DB_06[換算檢查],"OK")=1,INDEX(DB_06[乘數],MATCH(C5&"|"&K5,DB_06[換算鍵],0)),"")))) | M5: =UPPER(SUBSTITUTE(SUBSTITUTE(SUBSTITUTE(SUBSTITUTE(TRIM(B5&""),"＜","<"),"＞",">"),"≤","<="),"≥",">=")) | N5: =IF(M5="","",IF(OR(M5="ND",M5="N.D."),"ND",IF(OR(M5="NA",M5="N/A",M5="N.A."),"NA",IF(OR(LEFT(M5,2)="<=",LEFT(M5,2)=">="),LEFT(M5,2),IF(OR(LEFT(M5,1)="<",LEFT(M5,1)=">"),LEFT(M5,1),"數值"))))) | O5: =IF(OR(N5="",N5="ND",N5="NA"),"",IF(N5="數值",M5,TRIM(MID(M5,LEN(N5)+1,99)))) | P5: =IF(O5="","",IFERROR(IF(OR(OR(ISNUMBER(SEARCH("%",O5)),ISNUMBER(SEARCH(" ",O5)),ISNUMBER(SEARCH(",",O5))),OR(SUBSTITUTE(SUBSTITUTE(SUBSTITUTE(SUBSTITUTE(SUBSTITUTE(SUBSTITUTE(SUBSTITUTE(SUBSTITUTE(SUBSTITUTE(SUBSTITUTE(SUBSTITUTE(SUBSTITUTE(SUBSTITUTE(SUBSTITUTE(SUBSTITUTE(SUBSTITUTE(SUBSTITUTE(SUBSTITUTE("x"&O5,"0",""),"1",""),"2",""),"3",""),"4",""),"5",""),"6",""),"7",""),"8",""),"9",""),".",""),"E",""),"+",""),"-",""),"<",""),">",""),"=","")," ","")<>"x",ISNUMBER(SEARCH("-",SUBSTITUTE(SUBSTITUTE("x"&MID(O5,2,99),"E-","E"),"E+","E"))),ISNUMBER(SEARCH("+",SUBSTITUTE(SUBSTITUTE("x"&MID(O5,2,99),"E-","E"),"E+","E"))))),"",IF(ISNUMBER(AH5),AH5,NA())),"")) | Q5: =IF(AND(ISNUMBER(L5),ISNUMBER(P5)),L5*P5,"") | R5: =IF(OR(COUNTA($A5:$D5)=0,U5=0),"",IF(INDEX(DB_05[管制設定值],U5)="","",INDEX(DB_05[管制設定值],U5))) | S5: =IF(OR(COUNTA($A5:$D5)=0,U5=0),"",IF(INDEX(DB_05[監測設定值],U5)="","",INDEX(DB_05[監測設定值],U5))) | T5: =IF(COUNTA($A5:$D5)=0,"",IF(COUNTIFS(DB_04[測項鍵],V5)=1,MATCH(V5,DB_04[測項鍵],0),0)) | U5: =IF(COUNTA($A5:$D5)=0,"",IF(COUNTIFS(DB_05[標準鍵],W5)=1,MATCH(W5,DB_05[標準鍵],0),0)) | V5: =IF(OR(J5="",A5=""),"",J5&"|"&A5) | W5: =IF(OR('07_QAQC'!$C$3="",V5=""),"",'07_QAQC'!$C$3&"|"&V5) | X5: =IF(OR(H5="",A5=""),"",LEN(H5)&":"&H5&LEN(A5)&":"&A5) | Y5: =IF(COUNTA($A5:$D5)=0,"",IF(I5=0,"樣品未建或重複",IF(INDEX(Samples[樣品檢查],I5)="","OK",INDEX(Samples[樣品檢查],I5)))) | Z5: =IF(COUNTA($A5:$D5)=0,"",IF(B5="","缺原始值",IF(OR(B5="-",B5="--"),"無資料",IF(N5="NA","不適用",IF(N5="ND","OK",IF(NOT(ISNUMBER(P5)),"格式待核",IF(AND(N5<>"數值",P5<0),"界限不得為負","OK"))))))) | AA5: =IF(COUNTA(A5:D5)=0,"",IF(OR(A5="",H5=""),"缺識別欄位",IF(IF(LEN("="&SUBSTITUTE(SUBSTITUTE(SUBSTITUTE(X5,"~","~~"),"*","~*"),"?","~?"))<=255,COUNTIF(Results[結果識別鍵],"="&SUBSTITUTE(SUBSTITUTE(SUBSTITUTE(X5,"~","~~"),"*","~*"),"?","~?")),COUNTIFS(Results[關聯鍵],"="&SUBSTITUTE(SUBSTITUTE(SUBSTITUTE(H5,"~","~~"),"*","~*"),"?","~?"),Results[分析項目],"="&SUBSTITUTE(SUBSTITUTE(SUBSTITUTE(A5,"~","~~"),"*","~*"),"?","~?")))>1,"同關聯鍵測項重複","OK"))) | AB5: =IF(COUNTA($A5:$D5)=0,"",IF(OR(C5="",K5=""),"缺單位",IF(NOT(ISNUMBER(L5)),"單位不相容",IF(L5=1,"OK","已換算")))) | AC5: =IF(COUNTA($A5:$D5)=0,"",IF('07_QAQC'!$C$3="","未選比較版本",IF(U5=0,IF(COUNTIFS(DB_05[標準鍵],W5)>1,"標準鍵重複","未訂此介質／測項門檻"),IF(INDEX(DB_05[版本檢查],U5)<>"OK","標準主檔待核",IF(INDEX(DB_05[標準單位],U5)<>K5,"標準單位不符",IF(INDEX(DB_05[核對狀態],U5)="停用","停用",IF(F5="","缺採樣日期",IF(OR(AND(INDEX(DB_05[生效日],U5)<>"",F5<INDEX(DB_05[生效日],U5)),AND(INDEX(DB_05[失效日],U5)<>"",F5>INDEX(DB_05[失效日],U5))),"日期不適用",INDEX(DB_05[核對狀態],U5))))))))) | AD5: =IF(COUNTA($A5:$D5)=0,"",IF(AC5="未訂此介質／測項門檻",AC5,IF(AC5<>"已核對","標準待核",IF(R5="","未訂管制值",IF(NOT(ISNUMBER(L5)),"單位待核",IF(N5="ND","無法判定（ND無界限）",IF(N5="NA","不適用",IF(Z5<>"OK",Z5,IF(N5="數值",IF(Q5>=R5,"達管制值","未達管制值"),IF(OR(N5="<",N5="<="),IF(OR(Q5<R5,AND(N5="<",Q5=R5)),"未達管制值","無法判定"),IF(OR(N5=">",N5=">="),IF(Q5>=R5,"達管制值","無法判定"),"格式待核"))))))))))) | AE5: =IF(COUNTA($A5:$D5)=0,"",IF(AC5="未訂此介質／測項門檻",AC5,IF(AC5<>"已核對","標準待核",IF(S5="","未訂監測值",IF(NOT(ISNUMBER(L5)),"單位待核",IF(N5="ND","無法判定（ND無界限）",IF(N5="NA","不適用",IF(Z5<>"OK",Z5,IF(N5="數值",IF(Q5>=S5,"達監測值","未達監測值"),IF(OR(N5="<",N5="<="),IF(OR(Q5<S5,AND(N5="<",Q5=S5)),"未達監測值","無法判定"),IF(OR(N5=">",N5=">="),IF(Q5>=S5,"達監測值","無法判定"),"格式待核"))))))))))) | AF5: =IF(COUNTA($A5:$D5)=0,"",IF(OR(E5="",A5="",B5="",C5=""),"缺必要欄位",IF(Y5<>"OK","樣品資料待補",IF(T5=0,"測項未建或重複",IF(INDEX(DB_04[啟用],T5)<>"是","測項停用",IF(AND(Z5<>"OK",Z5<>"不適用"),Z5,IF(AND(AB5<>"OK",AB5<>"已換算"),"單位待核",IF(AA5<>"OK",AA5,"OK")))))))) | AG5: =IF(COUNTA($A5:$D5)=0,"",IF(N5="ND","ND取0",IF(OR(N5="<",N5="<="),"界限除以2",IF(N5="NA","不適用",IF(OR(N5=">",N5=">="),"保留界限數值","保留原數值"))))) | AH5: =IF(O5="","",IFERROR(_xlfn.NUMBERVALUE(O5,".",","),"")) | AI5: =IF(H5="","",IFERROR(MATCH(H5,Samples[樣品編號],0),0))
